Workbook

Sheet 0_Summary
A1: RAW MATERIAL | F1: BREAD COMPOSITION | L1: SENSORIAL | Q1: BREAD CRUMB POROSITY
A2: Parameter | B2: Sample | C2: Average (%) | D2: SD (%) | F2: Parameter | G2: Batch | H2: Sample | I2: Average (%) | J2: SD (%) | L2: Sample | M2: Test | N2: Avg Overall Points | O2: SD (%) | Q2: Test Name | R2: Avg 2D Porosity (%) | S2: SD 2D Porosity (%) | T2: Avg 3D Vol. (%) | U2: SD 3D Vol. (%) | V2: Avg Cell Count | W2: SD Cell Count | X2: Avg Cell Density (cells/cm²) | Y2: SD Cell Density | Z2: Avg Mean Cell Area (mm²) | AA2: SD Mean Cell Area
A3: Moisture | B3: Flour | C3: {=AVERAGEIFS( _xlfn.SWITCH(A3,"Moisture",'1_RawMaterial'!K:K,"Ash",'1_RawMaterial'!L:L,"Protein",'1_RawMaterial'!N:N,"Gluten",'1_RawMaterial'!P:P,"Fibre",'1_RawMaterial'!Q:Q), '1_RawMaterial'!D:D, A3, '1_RawMaterial'!C:C, B3 )} -> 0.12429887 | D3: {=_xlfn.STDEV.S( _xlfn._xlws.FILTER( _xlfn.SWITCH(A3,"Moisture",'1_RawMaterial'!K:K,"Ash",'1_RawMaterial'!L:L,"Protein",'1_RawMaterial'!N:N,"Gluten",'1_RawMaterial'!P:P,"Fibre",'1_RawMaterial'!Q:Q), ('1_RawMaterial'!D:D=A3)*('1_RawMaterial'!C:C=B3) ) )} -> 2.6363291e-05 | F3: Moisture | G3: A | H3: Flour | I3: {=IFERROR(_xlfn.LET(_xlpm.col,_xlfn.SWITCH($F3,"Moisture",'4_BreadComposition'!$K$2:$K$99,"Ash",'4_BreadComposition'!$M$2:$M$99,"Protein",'4_BreadComposition'!$O$2:$O$99,"Fibre",'4_BreadComposition'!$P$2:$P$99),_xlpm.f,_xlfn._xlws.FILTER(_xlpm.col,(TRIM('4_BreadComposition'!$D$2:$D$99)=TRIM($H3))*('4_BreadComposition'!$E$2:$E$99=$F3)*('4_BreadComposition'!$B$2:$B$99=$G3)*ISNUMBER(_xlpm.col)),AVERAGE(_xlpm.f)),"")} -> 0.093306693 | J3: {=IFERROR(_xlfn.LET(_xlpm.col,_xlfn.SWITCH($F3,"Moisture",'4_BreadComposition'!$K$2:$K$99,"Ash",'4_BreadComposition'!$M$2:$M$99,"Protein",'4_BreadComposition'!$O$2:$O$99,"Fibre",'4_BreadComposition'!$P$2:$P$99),_xlpm.f,_xlfn._xlws.FILTER(_xlpm.col,(TRIM('4_BreadComposition'!$D$2:$D$99)=TRIM($H3))*('4_BreadComposition'!$E$2:$E$99=$F3)*('4_BreadComposition'!$B$2:$B$99=$G3)*ISNUMBER(_xlpm.col)),_xlfn.STDEV.S(_xlpm.f)),"")} | L3: Flour | M3: 1 | N3: =AVERAGEIFS('5_Sensorial'!$N:$N, '5_Sensorial'!$B:$B, L3, '5_Sensorial'!$C:$C, M3) -> 82.5625 | O3: {=_xlfn.STDEV.S(IF(('5_Sensorial'!$B:$B=$L3)*('5_Sensorial'!$C:$C=$M3),'5_Sensorial'!$N:$N)) / AVERAGEIFS('5_Sensorial'!$N:$N,'5_Sensorial'!$B:$B,$L3,'5_Sensorial'!$C:$C,$M3) * 100} -> 9.0778971 | Q3: Flour | R3: =AVERAGEIF('6_BreadCrumbPorosity'!$B$2:$B$28,$Q3,'6_BreadCrumbPorosity'!D$2:D$28) -> 41.48 | S3: {=STDEV(IF('6_BreadCrumbPorosity'!$B$2:$B$28=$Q3,'6_BreadCrumbPorosity'!D$2:D$28))} -> 0.03 | T3: =AVERAGEIF('6_BreadCrumbPorosity'!$B$2:$B$28,$Q3,'6_BreadCrumbPorosity'!E$2:E$28) -> 62.216667 | U3: {=STDEV(IF('6_BreadCrumbPorosity'!$B$2:$B$28=$Q3,'6_BreadCrumbPorosity'!E$2:E$28))} -> 0.045092498 | V3: =AVERAGEIF('6_BreadCrumbPorosity'!$B$2:$B$28,$Q3,'6_BreadCrumbPorosity'!F$2:F$28) -> 812.33333 | W3: {=STDEV(IF('6_BreadCrumbPorosity'!$B$2:$B$28=$Q3,'6_BreadCrumbPorosity'!F$2:F$28))} -> 11.930353 | X3: =AVERAGEIF('6_BreadCrumbPorosity'!$B$2:$B$28,$Q3,'6_BreadCrumbPorosity'!G$2:G$28) -> 11.033333 | Y3: {=STDEV(IF('6_BreadCrumbPorosity'!$B$2:$B$28=$Q3,'6_BreadCrumbPorosity'!G$2:G$28))} -> 0.071360587 | Z3: =AVERAGEIF('6_BreadCrumbPorosity'!$B$2:$B$28,$Q3,'6_BreadCrumbPorosity'!H$2:H$28) -> 3.7596 | AA3: {=STDEV(IF('6_BreadCrumbPorosity'!$B$2:$B$28=$Q3,'6_BreadCrumbPorosity'!H$2:H$28))} -> 0.02694049
A4: Moisture | B4: BSG | C4: {=AVERAGEIFS( _xlfn.SWITCH(A4,"Moisture",'1_RawMaterial'!K:K,"Ash",'1_RawMaterial'!L:L,"Protein",'1_RawMaterial'!N:N,"Gluten",'1_RawMaterial'!P:P,"Fibre",'1_RawMaterial'!Q:Q), '1_RawMaterial'!D:D, A4, '1_RawMaterial'!C:C, B4 )} -> 0.049300202 | D4: {=_xlfn.STDEV.S( _xlfn._xlws.FILTER( _xlfn.SWITCH(A4,"Moisture",'1_RawMaterial'!K:K,"Ash",'1_RawMaterial'!L:L,"Protein",'1_RawMaterial'!N:N,"Gluten",'1_RawMaterial'!P:P,"Fibre",'1_RawMaterial'!Q:Q), ('1_RawMaterial'!D:D=A4)*('1_RawMaterial'!C:C=B4) ) )} -> 0.0010943033 | F4: Moisture | G4: A | H4: 10% BSG | I4: {=IFERROR(_xlfn.LET(_xlpm.col,_xlfn.SWITCH($F4,"Moisture",'4_BreadComposition'!$K$2:$K$99,"Ash",'4_BreadComposition'!$M$2:$M$99,"Protein",'4_BreadComposition'!$O$2:$O$99,"Fibre",'4_BreadComposition'!$P$2:$P$99),_xlpm.f,_xlfn._xlws.FILTER(_xlpm.col,(TRIM('4_BreadComposition'!$D$2:$D$99)=TRIM($H4))*('4_BreadComposition'!$E$2:$E$99=$F4)*('4_BreadComposition'!$B$2:$B$99=$G4)*ISNUMBER(_xlpm.col)),AVERAGE(_xlpm.f)),"")} -> 0.090241322 | J4: {=IFERROR(_xlfn.LET(_xlpm.col,_xlfn.SWITCH($F4,"Moisture",'4_BreadComposition'!$K$2:$K$99,"Ash",'4_BreadComposition'!$M$2:$M$99,"Protein",'4_BreadComposition'!$O$2:$O$99,"Fibre",'4_BreadComposition'!$P$2:$P$99),_xlpm.f,_xlfn._xlws.FILTER(_xlpm.col,(TRIM('4_BreadComposition'!$D$2:$D$99)=TRIM($H4))*('4_BreadComposition'!$E$2:$E$99=$F4)*('4_BreadComposition'!$B$2:$B$99=$G4)*ISNUMBER(_xlpm.col)),_xlfn.STDEV.S(_xlpm.f)),"")} | L4: 10% BSG | M4: 1 | N4: =AVERAGEIFS('5_Sensorial'!$N:$N, '5_Sensorial'!$B:$B, L4, '5_Sensorial'!$C:$C, M4) -> 76.75 | O4: {=_xlfn.STDEV.S(IF(('5_Sensorial'!$B:$B=$L4)*('5_Sensorial'!$C:$C=$M4),'5_Sensorial'!$N:$N)) / AVERAGEIFS('5_Sensorial'!$N:$N,'5_Sensorial'!$B:$B,$L4,'5_Sensorial'!$C:$C,$M4) * 100} -> 7.8716912 | Q4: 10% BSG+70ppmE | R4: =AVERAGEIF('6_BreadCrumbPorosity'!$B$2:$B$28,$Q4,'6_BreadCrumbPorosity'!D$2:D$28) -> 25.733333 | S4: {=STDEV(IF('6_BreadCrumbPorosity'!$B$2:$B$28=$Q4,'6_BreadCrumbPorosity'!D$2:D$28))} -> 0.45081408 | T4: =AVERAGEIF('6_BreadCrumbPorosity'!$B$2:$B$28,$Q4,'6_BreadCrumbPorosity'!E$2:E$28) -> 38.603333 | U4: {=STDEV(IF('6_BreadCrumbPorosity'!$B$2:$B$28=$Q4,'6_BreadCrumbPorosity'!E$2:E$28))} -> 0.67796263 | V4: =AVERAGEIF('6_BreadCrumbPorosity'!$B$2:$B$28,$Q4,'6_BreadCrumbPorosity'!F$2:F$28) -> 574 | W4: {=STDEV(IF('6_BreadCrumbPorosity'!$B$2:$B$28=$Q4,'6_BreadCrumbPorosity'!F$2:F$28))} -> 8.660254 | X4: =AVERAGEIF('6_BreadCrumbPorosity'!$B$2:$B$28,$Q4,'6_BreadCrumbPorosity'!G$2:G$28) -> 7.6126667 | Y4: {=STDEV(IF('6_BreadCrumbPorosity'!$B$2:$B$28=$Q4,'6_BreadCrumbPorosity'!G$2:G$28))} -> 0.092635486 | Z4: =AVERAGEIF('6_BreadCrumbPorosity'!$B$2:$B$28,$Q4,'6_BreadCrumbPorosity'!H$2:H$28) -> 3.3809 | AA4: {=STDEV(IF('6_BreadCrumbPorosity'!$B$2:$B$28=$Q4,'6_BreadCrumbPorosity'!H$2:H$28))} -> 0.058657566
A5: Moisture | B5: 10% BSG Mixture | C5: {=AVERAGEIFS( _xlfn.SWITCH(A5,"Moisture",'1_RawMaterial'!K:K,"Ash",'1_RawMaterial'!L:L,"Protein",'1_RawMaterial'!N:N,"Gluten",'1_RawMaterial'!P:P,"Fibre",'1_RawMaterial'!Q:Q), '1_RawMaterial'!D:D, A5, '1_RawMaterial'!C:C, B5 )} -> 0.11611839 | D5: {=_xlfn.STDEV.S( _xlfn._xlws.FILTER( _xlfn.SWITCH(A5,"Moisture",'1_RawMaterial'!K:K,"Ash",'1_RawMaterial'!L:L,"Protein",'1_RawMaterial'!N:N,"Gluten",'1_RawMaterial'!P:P,"Fibre",'1_RawMaterial'!Q:Q), ('1_RawMaterial'!D:D=A5)*('1_RawMaterial'!C:C=B5) ) )} -> 0.0010605541 | F5: Moisture | G5: A | H5: 20% BSG | I5: {=IFERROR(_xlfn.LET(_xlpm.col,_xlfn.SWITCH($F5,"Moisture",'4_BreadComposition'!$K$2:$K$99,"Ash",'4_BreadComposition'!$M$2:$M$99,"Protein",'4_BreadComposition'!$O$2:$O$99,"Fibre",'4_BreadComposition'!$P$2:$P$99),_xlpm.f,_xlfn._xlws.FILTER(_xlpm.col,(TRIM('4_BreadComposition'!$D$2:$D$99)=TRIM($H5))*('4_BreadComposition'!$E$2:$E$99=$F5)*('4_BreadComposition'!$B$2:$B$99=$G5)*ISNUMBER(_xlpm.col)),AVERAGE(_xlpm.f)),"")} -> 0.088480201 | J5: {=IFERROR(_xlfn.LET(_xlpm.col,_xlfn.SWITCH($F5,"Moisture",'4_BreadComposition'!$K$2:$K$99,"Ash",'4_BreadComposition'!$M$2:$M$99,"Protein",'4_BreadComposition'!$O$2:$O$99,"Fibre",'4_BreadComposition'!$P$2:$P$99),_xlpm.f,_xlfn._xlws.FILTER(_xlpm.col,(TRIM('4_BreadComposition'!$D$2:$D$99)=TRIM($H5))*('4_BreadComposition'!$E$2:$E$99=$F5)*('4_BreadComposition'!$B$2:$B$99=$G5)*ISNUMBER(_xlpm.col)),_xlfn.STDEV.S(_xlpm.f)),"")} | L5: 20% BSG | M5: 1 | N5: =AVERAGEIFS('5_Sensorial'!$N:$N, '5_Sensorial'!$B:$B, L5, '5_Sensorial'!$C:$C, M5) -> 54.625 | O5: {=_xlfn.STDEV.S(IF(('5_Sensorial'!$B:$B=$L5)*('5_Sensorial'!$C:$C=$M5),'5_Sensorial'!$N:$N)) / AVERAGEIFS('5_Sensorial'!$N:$N,'5_Sensorial'!$B:$B,$L5,'5_Sensorial'!$C:$C,$M5) * 100} -> 33.373318 | Q5: 20% BSG+70ppmE | R5: =AVERAGEIF('6_BreadCrumbPorosity'!$B$2:$B$28,$Q5,'6_BreadCrumbPorosity'!D$2:D$28) -> 19.663333 | S5: {=STDEV(IF('6_BreadCrumbPorosity'!$B$2:$B$28=$Q5,'6_BreadCrumbPorosity'!D$2:D$28))} -> 5.4096334 | T5: =AVERAGEIF('6_BreadCrumbPorosity'!$B$2:$B$28,$Q5,'6_BreadCrumbPorosity'!E$2:E$28) -> 29.496667 | U5: {=STDEV(IF('6_BreadCrumbPorosity'!$B$2:$B$28=$Q5,'6_BreadCrumbPorosity'!E$2:E$28))} -> 8.1188074 | V5: =AVERAGEIF('6_BreadCrumbPorosity'!$B$2:$B$28,$Q5,'6_BreadCrumbPorosity'!F$2:F$28) -> 386.66667 | W5: {=STDEV(IF('6_BreadCrumbPorosity'!$B$2:$B$28=$Q5,'6_BreadCrumbPorosity'!F$2:F$28))} -> 96.173454 | X5: =AVERAGEIF('6_BreadCrumbPorosity'!$B$2:$B$28,$Q5,'6_BreadCrumbPorosity'!G$2:G$28) -> 6.0316667 | Y5: {=STDEV(IF('6_BreadCrumbPorosity'!$B$2:$B$28=$Q5,'6_BreadCrumbPorosity'!G$2:G$28))} -> 1.5314311 | Z5: =AVERAGEIF('6_BreadCrumbPorosity'!$B$2:$B$28,$Q5,'6_BreadCrumbPorosity'!H$2:H$28) -> 3.2996 | AA5: {=STDEV(IF('6_BreadCrumbPorosity'!$B$2:$B$28=$Q5,'6_BreadCrumbPorosity'!H$2:H$28))} -> 0.61215825
A6: Moisture | B6: 20% BSG Mixture | C6: {=AVERAGEIFS( _xlfn.SWITCH(A6,"Moisture",'1_RawMaterial'!K:K,"Ash",'1_RawMaterial'!L:L,"Protein",'1_RawMaterial'!N:N,"Gluten",'1_RawMaterial'!P:P,"Fibre",'1_RawMaterial'!Q:Q), '1_RawMaterial'!D:D, A6, '1_RawMaterial'!C:C, B6 )} -> 0.10679947 | D6: {=_xlfn.STDEV.S( _xlfn._xlws.FILTER( _xlfn.SWITCH(A6,"Moisture",'1_RawMaterial'!K:K,"Ash",'1_RawMaterial'!L:L,"Protein",'1_RawMaterial'!N:N,"Gluten",'1_RawMaterial'!P:P,"Fibre",'1_RawMaterial'!Q:Q), ('1_RawMaterial'!D:D=A6)*('1_RawMaterial'!C:C=B6) ) )} -> 0.0021503512 | F6: Moisture | G6: A | H6: 10% BSG+70ppmE | I6: {=IFERROR(_xlfn.LET(_xlpm.col,_xlfn.SWITCH($F6,"Moisture",'4_BreadComposition'!$K$2:$K$99,"Ash",'4_BreadComposition'!$M$2:$M$99,"Protein",'4_BreadComposition'!$O$2:$O$99,"Fibre",'4_BreadComposition'!$P$2:$P$99),_xlpm.f,_xlfn._xlws.FILTER(_xlpm.col,(TRIM('4_BreadComposition'!$D$2:$D$99)=TRIM($H6))*('4_BreadComposition'!$E$2:$E$99=$F6)*('4_BreadComposition'!$B$2:$B$99=$G6)*ISNUMBER(_xlpm.col)),AVERAGE(_xlpm.f)),"")} -> 0.088792983 | J6: {=IFERROR(_xlfn.LET(_xlpm.col,_xlfn.SWITCH($F6,"Moisture",'4_BreadComposition'!$K$2:$K$99,"Ash",'4_BreadComposition'!$M$2:$M$99,"Protein",'4_BreadComposition'!$O$2:$O$99,"Fibre",'4_BreadComposition'!$P$2:$P$99),_xlpm.f,_xlfn._xlws.FILTER(_xlpm.col,(TRIM('4_BreadComposition'!$D$2:$D$99)=TRIM($H6))*('4_BreadComposition'!$E$2:$E$99=$F6)*('4_BreadComposition'!$B$2:$B$99=$G6)*ISNUMBER(_xlpm.col)),_xlfn.STDEV.S(_xlpm.f)),"")} | L6: 10% BSG+70ppmE | M6: 1 | N6: =AVERAGEIFS('5_Sensorial'!$N:$N, '5_Sensorial'!$B:$B, L6, '5_Sensorial'!$C:$C, M6) -> 65.25 | O6: {=_xlfn.STDEV.S(IF(('5_Sensorial'!$B:$B=$L6)*('5_Sensorial'!$C:$C=$M6),'5_Sensorial'!$N:$N)) / AVERAGEIFS('5_Sensorial'!$N:$N,'5_Sensorial'!$B:$B,$L6,'5_Sensorial'!$C:$C,$M6) * 100} -> 16.688201 | Q6: 10% BSG_fraction+70ppmE | R6: =AVERAGEIF('6_BreadCrumbPorosity'!$B$2:$B$28,$Q6,'6_BreadCrumbPorosity'!D$2:D$28) -> 27.823333 | S6: {=STDEV(IF('6_BreadCrumbPorosity'!$B$2:$B$28=$Q6,'6_BreadCrumbPorosity'!D$2:D$28))} -> 1.8283964 | T6: =AVERAGEIF('6_BreadCrumbPorosity'!$B$2:$B$28,$Q6,'6_BreadCrumbPorosity'!E$2:E$28) -> 41.733333 | U6: {=STDEV(IF('6_BreadCrumbPorosity'!$B$2:$B$28=$Q6,'6_BreadCrumbPorosity'!E$2:E$28))} -> 2.7452929 | V6: =AVERAGEIF('6_BreadCrumbPorosity'!$B$2:$B$28,$Q6,'6_BreadCrumbPorosity'!F$2:F$28) -> 640.33333 | W6: {=STDEV(IF('6_BreadCrumbPorosity'!$B$2:$B$28=$Q6,'6_BreadCrumbPorosity'!F$2:F$28))} -> 57.35271 | X6: =AVERAGEIF('6_BreadCrumbPorosity'!$B$2:$B$28,$Q6,'6_BreadCrumbPorosity'!G$2:G$28) -> 8.1276667 | Y6: {=STDEV(IF('6_BreadCrumbPorosity'!$B$2:$B$28=$Q6,'6_BreadCrumbPorosity'!G$2:G$28))} -> 0.47510455 | Z6: =AVERAGEIF('6_BreadCrumbPorosity'!$B$2:$B$28,$Q6,'6_BreadCrumbPorosity'!H$2:H$28) -> 3.4394667 | AA6: {=STDEV(IF('6_BreadCrumbPorosity'!$B$2:$B$28=$Q6,'6_BreadCrumbPorosity'!H$2:H$28))} -> 0.42234325
A7: Ash | B7: Flour | C7: {=AVERAGEIFS( _xlfn.SWITCH(A7,"Moisture",'1_RawMaterial'!K:K,"Ash",'1_RawMaterial'!L:L,"Protein",'1_RawMaterial'!N:N,"Gluten",'1_RawMaterial'!P:P,"Fibre",'1_RawMaterial'!Q:Q), '1_RawMaterial'!D:D, A7, '1_RawMaterial'!C:C, B7 )} -> 0.0066165097 | D7: {=_xlfn.STDEV.S( _xlfn._xlws.FILTER( _xlfn.SWITCH(A7,"Moisture",'1_RawMaterial'!K:K,"Ash",'1_RawMaterial'!L:L,"Protein",'1_RawMaterial'!N:N,"Gluten",'1_RawMaterial'!P:P,"Fibre",'1_RawMaterial'!Q:Q), ('1_RawMaterial'!D:D=A7)*('1_RawMaterial'!C:C=B7) ) )} -> 0.00044969074 | F7: Moisture | G7: A | H7: 20% BSG+70ppmE | I7: {=IFERROR(_xlfn.LET(_xlpm.col,_xlfn.SWITCH($F7,"Moisture",'4_BreadComposition'!$K$2:$K$99,"Ash",'4_BreadComposition'!$M$2:$M$99,"Protein",'4_BreadComposition'!$O$2:$O$99,"Fibre",'4_BreadComposition'!$P$2:$P$99),_xlpm.f,_xlfn._xlws.FILTER(_xlpm.col,(TRIM('4_BreadComposition'!$D$2:$D$99)=TRIM($H7))*('4_BreadComposition'!$E$2:$E$99=$F7)*('4_BreadComposition'!$B$2:$B$99=$G7)*ISNUMBER(_xlpm.col)),AVERAGE(_xlpm.f)),"")} -> 0.087746262 | J7: {=IFERROR(_xlfn.LET(_xlpm.col,_xlfn.SWITCH($F7,"Moisture",'4_BreadComposition'!$K$2:$K$99,"Ash",'4_BreadComposition'!$M$2:$M$99,"Protein",'4_BreadComposition'!$O$2:$O$99,"Fibre",'4_BreadComposition'!$P$2:$P$99),_xlpm.f,_xlfn._xlws.FILTER(_xlpm.col,(TRIM('4_BreadComposition'!$D$2:$D$99)=TRIM($H7))*('4_BreadComposition'!$E$2:$E$99=$F7)*('4_BreadComposition'!$B$2:$B$99=$G7)*ISNUMBER(_xlpm.col)),_xlfn.STDEV.S(_xlpm.f)),"")} | L7: 20% BSG+70ppmE | M7: 1 | N7: =AVERAGEIFS('5_Sensorial'!$N:$N, '5_Sensorial'!$B:$B, L7, '5_Sensorial'!$C:$C, M7) -> 51.5625 | O7: {=_xlfn.STDEV.S(IF(('5_Sensorial'!$B:$B=$L7)*('5_Sensorial'!$C:$C=$M7),'5_Sensorial'!$N:$N)) / AVERAGEIFS('5_Sensorial'!$N:$N,'5_Sensorial'!$B:$B,$L7,'5_Sensorial'!$C:$C,$M7) * 100} -> 39.969659 | Q7: 20% BSG_fraction+70ppmE | R7: =AVERAGEIF('6_BreadCrumbPorosity'!$B$2:$B$28,$Q7,'6_BreadCrumbPorosity'!D$2:D$28) -> 22.756667 | S7: {=STDEV(IF('6_BreadCrumbPorosity'!$B$2:$B$28=$Q7,'6_BreadCrumbPorosity'!D$2:D$28))} -> 0.80407297 | T7: =AVERAGEIF('6_BreadCrumbPorosity'!$B$2:$B$28,$Q7,'6_BreadCrumbPorosity'!E$2:E$28) -> 34.136667 | U7: {=STDEV(IF('6_BreadCrumbPorosity'!$B$2:$B$28=$Q7,'6_BreadCrumbPorosity'!E$2:E$28))} -> 1.2035503 | V7: =AVERAGEIF('6_BreadCrumbPorosity'!$B$2:$B$28,$Q7,'6_BreadCrumbPorosity'!F$2:F$28) -> 585.33333 | W7: {=STDEV(IF('6_BreadCrumbPorosity'!$B$2:$B$28=$Q7,'6_BreadCrumbPorosity'!F$2:F$28))} -> 21.548395 | X7: =AVERAGEIF('6_BreadCrumbPorosity'!$B$2:$B$28,$Q7,'6_BreadCrumbPorosity'!G$2:G$28) -> 9.729 | Y7: {=STDEV(IF('6_BreadCrumbPorosity'!$B$2:$B$28=$Q7,'6_BreadCrumbPorosity'!G$2:G$28))} -> 0.21017374 | Z7: =AVERAGEIF('6_BreadCrumbPorosity'!$B$2:$B$28,$Q7,'6_BreadCrumbPorosity'!H$2:H$28) -> 2.3410333 | AA7: {=STDEV(IF('6_BreadCrumbPorosity'!$B$2:$B$28=$Q7,'6_BreadCrumbPorosity'!H$2:H$28))} -> 0.13050909
A8: Ash | B8: BSG | C8: {=AVERAGEIFS( _xlfn.SWITCH(A8,"Moisture",'1_RawMaterial'!K:K,"Ash",'1_RawMaterial'!L:L,"Protein",'1_RawMaterial'!N:N,"Gluten",'1_RawMaterial'!P:P,"Fibre",'1_RawMaterial'!Q:Q), '1_RawMaterial'!D:D, A8, '1_RawMaterial'!C:C, B8 )} -> 0.040405881 | D8: {=_xlfn.STDEV.S( _xlfn._xlws.FILTER( _xlfn.SWITCH(A8,"Moisture",'1_RawMaterial'!K:K,"Ash",'1_RawMaterial'!L:L,"Protein",'1_RawMaterial'!N:N,"Gluten",'1_RawMaterial'!P:P,"Fibre",'1_RawMaterial'!Q:Q), ('1_RawMaterial'!D:D=A8)*('1_RawMaterial'!C:C=B8) ) )} -> 0.00044581066 | F8: Moisture | G8: B | H8: Flour | I8: {=IFERROR(_xlfn.LET(_xlpm.col,_xlfn.SWITCH($F8,"Moisture",'4_BreadComposition'!$K$2:$K$99,"Ash",'4_BreadComposition'!$M$2:$M$99,"Protein",'4_BreadComposition'!$O$2:$O$99,"Fibre",'4_BreadComposition'!$P$2:$P$99),_xlpm.f,_xlfn._xlws.FILTER(_xlpm.col,(TRIM('4_BreadComposition'!$D$2:$D$99)=TRIM($H8))*('4_BreadComposition'!$E$2:$E$99=$F8)*('4_BreadComposition'!$B$2:$B$99=$G8)*ISNUMBER(_xlpm.col)),AVERAGE(_xlpm.f)),"")} -> 0.0869 | J8: {=IFERROR(_xlfn.LET(_xlpm.col,_xlfn.SWITCH($F8,"Moisture",'4_BreadComposition'!$K$2:$K$99,"Ash",'4_BreadComposition'!$M$2:$M$99,"Protein",'4_BreadComposition'!$O$2:$O$99,"Fibre",'4_BreadComposition'!$P$2:$P$99),_xlpm.f,_xlfn._xlws.FILTER(_xlpm.col,(TRIM('4_BreadComposition'!$D$2:$D$99)=TRIM($H8))*('4_BreadComposition'!$E$2:$E$99=$F8)*('4_BreadComposition'!$B$2:$B$99=$G8)*ISNUMBER(_xlpm.col)),_xlfn.STDEV.S(_xlpm.f)),"")} | L8: Flour | M8: 2 | N8: =AVERAGEIFS('5_Sensorial'!$N:$N, '5_Sensorial'!$B:$B, L8, '5_Sensorial'!$C:$C, M8) -> 85.9375 | O8: {=_xlfn.STDEV.S(IF(('5_Sensorial'!$B:$B=$L8)*('5_Sensorial'!$C:$C=$M8),'5_Sensorial'!$N:$N)) / AVERAGEIFS('5_Sensorial'!$N:$N,'5_Sensorial'!$B:$B,$L8,'5_Sensorial'!$C:$C,$M8) * 100} -> 15.764213 | Q8: 10% BSG+140ppmE | R8: =AVERAGEIF('6_BreadCrumbPorosity'!$B$2:$B$28,$Q8,'6_BreadCrumbPorosity'!D$2:D$28) -> 24.9 | S8: {=STDEV(IF('6_BreadCrumbPorosity'!$B$2:$B$28=$Q8,'6_BreadCrumbPorosity'!D$2:D$28))} -> 2.6303422 | T8: =AVERAGEIF('6_BreadCrumbPorosity'!$B$2:$B$28,$Q8,'6_BreadCrumbPorosity'!E$2:E$28) -> 37.353333 | U8: {=STDEV(IF('6_BreadCrumbPorosity'!$B$2:$B$28=$Q8,'6_BreadCrumbPorosity'!E$2:E$28))} -> 3.9513331 | V8: =AVERAGEIF('6_BreadCrumbPorosity'!$B$2:$B$28,$Q8,'6_BreadCrumbPorosity'!F$2:F$28) -> 506 | W8: {=STDEV(IF('6_BreadCrumbPorosity'!$B$2:$B$28=$Q8,'6_BreadCrumbPorosity'!F$2:F$28))} -> 142.20056 | X8: =AVERAGEIF('6_BreadCrumbPorosity'!$B$2:$B$28,$Q8,'6_BreadCrumbPorosity'!G$2:G$28) -> 5.1096667 | Y8: {=STDEV(IF('6_BreadCrumbPorosity'!$B$2:$B$28=$Q8,'6_BreadCrumbPorosity'!G$2:G$28))} -> 0.13969371 | Z8: =AVERAGEIF('6_BreadCrumbPorosity'!$B$2:$B$28,$Q8,'6_BreadCrumbPorosity'!H$2:H$28) -> 4.8789 | AA8: {=STDEV(IF('6_BreadCrumbPorosity'!$B$2:$B$28=$Q8,'6_BreadCrumbPorosity'!H$2:H$28))} -> 0.56915728
A9: Ash | B9: 10% BSG Mixture | C9: {=AVERAGEIFS( _xlfn.SWITCH(A9,"Moisture",'1_RawMaterial'!K:K,"Ash",'1_RawMaterial'!L:L,"Protein",'1_RawMaterial'!N:N,"Gluten",'1_RawMaterial'!P:P,"Fibre",'1_RawMaterial'!Q:Q), '1_RawMaterial'!D:D, A9, '1_RawMaterial'!C:C, B9 )} -> 0.010114473 | D9: {=_xlfn.STDEV.S( _xlfn._xlws.FILTER( _xlfn.SWITCH(A9,"Moisture",'1_RawMaterial'!K:K,"Ash",'1_RawMaterial'!L:L,"Protein",'1_RawMaterial'!N:N,"Gluten",'1_RawMaterial'!P:P,"Fibre",'1_RawMaterial'!Q:Q), ('1_RawMaterial'!D:D=A9)*('1_RawMaterial'!C:C=B9) ) )} -> 2.1896679e-05 | F9: Moisture | G9: B | H9: 10% BSG+70ppmE | I9: {=IFERROR(_xlfn.LET(_xlpm.col,_xlfn.SWITCH($F9,"Moisture",'4_BreadComposition'!$K$2:$K$99,"Ash",'4_BreadComposition'!$M$2:$M$99,"Protein",'4_BreadComposition'!$O$2:$O$99,"Fibre",'4_BreadComposition'!$P$2:$P$99),_xlpm.f,_xlfn._xlws.FILTER(_xlpm.col,(TRIM('4_BreadComposition'!$D$2:$D$99)=TRIM($H9))*('4_BreadComposition'!$E$2:$E$99=$F9)*('4_BreadComposition'!$B$2:$B$99=$G9)*ISNUMBER(_xlpm.col)),AVERAGE(_xlpm.f)),"")} -> 0.0874 | J9: {=IFERROR(_xlfn.LET(_xlpm.col,_xlfn.SWITCH($F9,"Moisture",'4_BreadComposition'!$K$2:$K$99,"Ash",'4_BreadComposition'!$M$2:$M$99,"Protein",'4_BreadComposition'!$O$2:$O$99,"Fibre",'4_BreadComposition'!$P$2:$P$99),_xlpm.f,_xlfn._xlws.FILTER(_xlpm.col,(TRIM('4_BreadComposition'!$D$2:$D$99)=TRIM($H9))*('4_BreadComposition'!$E$2:$E$99=$F9)*('4_BreadComposition'!$B$2:$B$99=$G9)*ISNUMBER(_xlpm.col)),_xlfn.STDEV.S(_xlpm.f)),"")} | L9: 10% BSG+70ppmE | M9: 2 | N9: =AVERAGEIFS('5_Sensorial'!$N:$N, '5_Sensorial'!$B:$B, L9, '5_Sensorial'!$C:$C, M9) -> 81.75 | O9: {=_xlfn.STDEV.S(IF(('5_Sensorial'!$B:$B=$L9)*('5_Sensorial'!$C:$C=$M9),'5_Sensorial'!$N:$N)) / AVERAGEIFS('5_Sensorial'!$N:$N,'5_Sensorial'!$B:$B,$L9,'5_Sensorial'!$C:$C,$M9) * 100} -> 13.089257 | Q9: 20% BSG+140ppmE | R9: =AVERAGEIF('6_BreadCrumbPorosity'!$B$2:$B$28,$Q9,'6_BreadCrumbPorosity'!D$2:D$28) -> 19.386667 | S9: {=STDEV(IF('6_BreadCrumbPorosity'!$B$2:$B$28=$Q9,'6_BreadCrumbPorosity'!D$2:D$28))} -> 2.7274591 | T9: =AVERAGEIF('6_BreadCrumbPorosity'!$B$2:$B$28,$Q9,'6_BreadCrumbPorosity'!E$2:E$28) -> 29.076667 | U9: {=STDEV(IF('6_BreadCrumbPorosity'!$B$2:$B$28=$Q9,'6_BreadCrumbPorosity'!E$2:E$28))} -> 4.0885246 | V9: =AVERAGEIF('6_BreadCrumbPorosity'!$B$2:$B$28,$Q9,'6_BreadCrumbPorosity'!F$2:F$28) -> 565.66667 | W9: {=STDEV(IF('6_BreadCrumbPorosity'!$B$2:$B$28=$Q9,'6_BreadCrumbPorosity'!F$2:F$28))} -> 17.785762 | X9: =AVERAGEIF('6_BreadCrumbPorosity'!$B$2:$B$28,$Q9,'6_BreadCrumbPorosity'!G$2:G$28) -> 7.427 | Y9: {=STDEV(IF('6_BreadCrumbPorosity'!$B$2:$B$28=$Q9,'6_BreadCrumbPorosity'!G$2:G$28))} -> 0.22260279 | Z9: =AVERAGEIF('6_BreadCrumbPorosity'!$B$2:$B$28,$Q9,'6_BreadCrumbPorosity'!H$2:H$28) -> 2.6174 | AA9: {=STDEV(IF('6_BreadCrumbPorosity'!$B$2:$B$28=$Q9,'6_BreadCrumbPorosity'!H$2:H$28))} -> 0.43246915
A10: Ash | B10: 20% BSG Mixture | C10: {=AVERAGEIFS( _xlfn.SWITCH(A10,"Moisture",'1_RawMaterial'!K:K,"Ash",'1_RawMaterial'!L:L,"Protein",'1_RawMaterial'!N:N,"Gluten",'1_RawMaterial'!P:P,"Fibre",'1_RawMaterial'!Q:Q), '1_RawMaterial'!D:D, A10, '1_RawMaterial'!C:C, B10 )} -> 0.013383998 | D10: {=_xlfn.STDEV.S( _xlfn._xlws.FILTER( _xlfn.SWITCH(A10,"Moisture",'1_RawMaterial'!K:K,"Ash",'1_RawMaterial'!L:L,"Protein",'1_RawMaterial'!N:N,"Gluten",'1_RawMaterial'!P:P,"Fibre",'1_RawMaterial'!Q:Q), ('1_RawMaterial'!D:D=A10)*('1_RawMaterial'!C:C=B10) ) )} -> 6.9136816e-05 | F10: Moisture | G10: B | H10: 20% BSG+70ppmE | I10: {=IFERROR(_xlfn.LET(_xlpm.col,_xlfn.SWITCH($F10,"Moisture",'4_BreadComposition'!$K$2:$K$99,"Ash",'4_BreadComposition'!$M$2:$M$99,"Protein",'4_BreadComposition'!$O$2:$O$99,"Fibre",'4_BreadComposition'!$P$2:$P$99),_xlpm.f,_xlfn._xlws.FILTER(_xlpm.col,(TRIM('4_BreadComposition'!$D$2:$D$99)=TRIM($H10))*('4_BreadComposition'!$E$2:$E$99=$F10)*('4_BreadComposition'!$B$2:$B$99=$G10)*ISNUMBER(_xlpm.col)),AVERAGE(_xlpm.f)),"")} -> 0.0863 | J10: {=IFERROR(_xlfn.LET(_xlpm.col,_xlfn.SWITCH($F10,"Moisture",'4_BreadComposition'!$K$2:$K$99,"Ash",'4_BreadComposition'!$M$2:$M$99,"Protein",'4_BreadComposition'!$O$2:$O$99,"Fibre",'4_BreadComposition'!$P$2:$P$99),_xlpm.f,_xlfn._xlws.FILTER(_xlpm.col,(TRIM('4_BreadComposition'!$D$2:$D$99)=TRIM($H10))*('4_BreadComposition'!$E$2:$E$99=$F10)*('4_BreadComposition'!$B$2:$B$99=$G10)*ISNUMBER(_xlpm.col)),_xlfn.STDEV.S(_xlpm.f)),"")} | L10: 20% BSG+70ppmE | M10: 2 | N10: =AVERAGEIFS('5_Sensorial'!$N:$N, '5_Sensorial'!$B:$B, L10, '5_Sensorial'!$C:$C, M10) -> 56.8125 | O10: {=_xlfn.STDEV.S(IF(('5_Sensorial'!$B:$B=$L10)*('5_Sensorial'!$C:$C=$M10),'5_Sensorial'!$N:$N)) / AVERAGEIFS('5_Sensorial'!$N:$N,'5_Sensorial'!$B:$B,$L10,'5_Sensorial'!$C:$C,$M10) * 100} -> 22.511472 | Q10: 10% BSG_fraction+140ppmE | R10: =AVERAGEIF('6_BreadCrumbPorosity'!$B$2:$B$28,$Q10,'6_BreadCrumbPorosity'!D$2:D$28) -> 16.2 | S10: {=STDEV(IF('6_BreadCrumbPorosity'!$B$2:$B$28=$Q10,'6_BreadCrumbPorosity'!D$2:D$28))} -> 1.099136 | T10: =AVERAGEIF('6_BreadCrumbPorosity'!$B$2:$B$28,$Q10,'6_BreadCrumbPorosity'!E$2:E$28) -> 24.3 | U10: {=STDEV(IF('6_BreadCrumbPorosity'!$B$2:$B$28=$Q10,'6_BreadCrumbPorosity'!E$2:E$28))} -> 1.6416151 | V10: =AVERAGEIF('6_BreadCrumbPorosity'!$B$2:$B$28,$Q10,'6_BreadCrumbPorosity'!F$2:F$28) -> 673.33333 | W10: {=STDEV(IF('6_BreadCrumbPorosity'!$B$2:$B$28=$Q10,'6_BreadCrumbPorosity'!F$2:F$28))} -> 34.961884 | X10: =AVERAGEIF('6_BreadCrumbPorosity'!$B$2:$B$28,$Q10,'6_BreadCrumbPorosity'!G$2:G$28) -> 9.878 | Y10: {=STDEV(IF('6_BreadCrumbPorosity'!$B$2:$B$28=$Q10,'6_BreadCrumbPorosity'!G$2:G$28))} -> 0.11781766 | Z10: =AVERAGEIF('6_BreadCrumbPorosity'!$B$2:$B$28,$Q10,'6_BreadCrumbPorosity'!H$2:H$28) -> 1.6402667 | AA10: {=STDEV(IF('6_BreadCrumbPorosity'!$B$2:$B$28=$Q10,'6_BreadCrumbPorosity'!H$2:H$28))} -> 0.11771025
A11: Protein | B11: Flour | C11: {=AVERAGEIFS( _xlfn.SWITCH(A11,"Moisture",'1_RawMaterial'!K:K,"Ash",'1_RawMaterial'!L:L,"Protein",'1_RawMaterial'!N:N,"Gluten",'1_RawMaterial'!P:P,"Fibre",'1_RawMaterial'!Q:Q), '1_RawMaterial'!D:D, A11, '1_RawMaterial'!C:C, B11 )} -> 12.9 | D11: {=_xlfn.STDEV.S( _xlfn._xlws.FILTER( _xlfn.SWITCH(A11,"Moisture",'1_RawMaterial'!K:K,"Ash",'1_RawMaterial'!L:L,"Protein",'1_RawMaterial'!N:N,"Gluten",'1_RawMaterial'!P:P,"Fibre",'1_RawMaterial'!Q:Q), ('1_RawMaterial'!D:D=A11)*('1_RawMaterial'!C:C=B11) ) )} -> 0.14142136 | F11: Moisture | G11: B | H11: 10% BSG_fraction+70ppmE | I11: {=IFERROR(_xlfn.LET(_xlpm.col,_xlfn.SWITCH($F11,"Moisture",'4_BreadComposition'!$K$2:$K$99,"Ash",'4_BreadComposition'!$M$2:$M$99,"Protein",'4_BreadComposition'!$O$2:$O$99,"Fibre",'4_BreadComposition'!$P$2:$P$99),_xlpm.f,_xlfn._xlws.FILTER(_xlpm.col,(TRIM('4_BreadComposition'!$D$2:$D$99)=TRIM($H11))*('4_BreadComposition'!$E$2:$E$99=$F11)*('4_BreadComposition'!$B$2:$B$99=$G11)*ISNUMBER(_xlpm.col)),AVERAGE(_xlpm.f)),"")} -> 0.0866 | J11: {=IFERROR(_xlfn.LET(_xlpm.col,_xlfn.SWITCH($F11,"Moisture",'4_BreadComposition'!$K$2:$K$99,"Ash",'4_BreadComposition'!$M$2:$M$99,"Protein",'4_BreadComposition'!$O$2:$O$99,"Fibre",'4_BreadComposition'!$P$2:$P$99),_xlpm.f,_xlfn._xlws.FILTER(_xlpm.col,(TRIM('4_BreadComposition'!$D$2:$D$99)=TRIM($H11))*('4_BreadComposition'!$E$2:$E$99=$F11)*('4_BreadComposition'!$B$2:$B$99=$G11)*ISNUMBER(_xlpm.col)),_xlfn.STDEV.S(_xlpm.f)),"")} | L11: 10% BSG_fraction+70ppmE | M11: 2 | N11: =AVERAGEIFS('5_Sensorial'!$N:$N, '5_Sensorial'!$B:$B, L11, '5_Sensorial'!$C:$C, M11) -> 85 | O11: {=_xlfn.STDEV.S(IF(('5_Sensorial'!$B:$B=$L11)*('5_Sensorial'!$C:$C=$M11),'5_Sensorial'!$N:$N)) / AVERAGEIFS('5_Sensorial'!$N:$N,'5_Sensorial'!$B:$B,$L11,'5_Sensorial'!$C:$C,$M11) * 100} -> 8.0162958 | Q11: 20% BSG_fraction+140ppmE | R11: =AVERAGEIF('6_BreadCrumbPorosity'!$B$2:$B$28,$Q11,'6_BreadCrumbPorosity'!D$2:D$28) -> 22.683333 | S11: {=STDEV(IF('6_BreadCrumbPorosity'!$B$2:$B$28=$Q11,'6_BreadCrumbPorosity'!D$2:D$28))} -> 2.8309068 | T11: =AVERAGEIF('6_BreadCrumbPorosity'!$B$2:$B$28,$Q11,'6_BreadCrumbPorosity'!E$2:E$28) -> 34.026667 | U11: {=STDEV(IF('6_BreadCrumbPorosity'!$B$2:$B$28=$Q11,'6_BreadCrumbPorosity'!E$2:E$28))} -> 4.2508391 | V11: =AVERAGEIF('6_BreadCrumbPorosity'!$B$2:$B$28,$Q11,'6_BreadCrumbPorosity'!F$2:F$28) -> 676.66667 | W11: {=STDEV(IF('6_BreadCrumbPorosity'!$B$2:$B$28=$Q11,'6_BreadCrumbPorosity'!F$2:F$28))} -> 18.147543 | X11: =AVERAGEIF('6_BreadCrumbPorosity'!$B$2:$B$28,$Q11,'6_BreadCrumbPorosity'!G$2:G$28) -> 9.7 | Y11: {=STDEV(IF('6_BreadCrumbPorosity'!$B$2:$B$28=$Q11,'6_BreadCrumbPorosity'!G$2:G$28))} -> 0.34517966 | Z11: =AVERAGEIF('6_BreadCrumbPorosity'!$B$2:$B$28,$Q11,'6_BreadCrumbPorosity'!H$2:H$28) -> 2.3468667 | AA11: {=STDEV(IF('6_BreadCrumbPorosity'!$B$2:$B$28=$Q11,'6_BreadCrumbPorosity'!H$2:H$28))} -> 0.37339875
A12: Protein | B12: BSG | C12: {=AVERAGEIFS( _xlfn.SWITCH(A12,"Moisture",'1_RawMaterial'!K:K,"Ash",'1_RawMaterial'!L:L,"Protein",'1_RawMaterial'!N:N,"Gluten",'1_RawMaterial'!P:P,"Fibre",'1_RawMaterial'!Q:Q), '1_RawMaterial'!D:D, A12, '1_RawMaterial'!C:C, B12 )} -> 23.65 | D12: {=_xlfn.STDEV.S( _xlfn._xlws.FILTER( _xlfn.SWITCH(A12,"Moisture",'1_RawMaterial'!K:K,"Ash",'1_RawMaterial'!L:L,"Protein",'1_RawMaterial'!N:N,"Gluten",'1_RawMaterial'!P:P,"Fibre",'1_RawMaterial'!Q:Q), ('1_RawMaterial'!D:D=A12)*('1_RawMaterial'!C:C=B12) ) )} -> 0.21213203 | F12: Moisture | G12: B | H12: 20% BSG_fraction+70ppmE | I12: {=IFERROR(_xlfn.LET(_xlpm.col,_xlfn.SWITCH($F12,"Moisture",'4_BreadComposition'!$K$2:$K$99,"Ash",'4_BreadComposition'!$M$2:$M$99,"Protein",'4_BreadComposition'!$O$2:$O$99,"Fibre",'4_BreadComposition'!$P$2:$P$99),_xlpm.f,_xlfn._xlws.FILTER(_xlpm.col,(TRIM('4_BreadComposition'!$D$2:$D$99)=TRIM($H12))*('4_BreadComposition'!$E$2:$E$99=$F12)*('4_BreadComposition'!$B$2:$B$99=$G12)*ISNUMBER(_xlpm.col)),AVERAGE(_xlpm.f)),"")} -> 0.0849 | J12: {=IFERROR(_xlfn.LET(_xlpm.col,_xlfn.SWITCH($F12,"Moisture",'4_BreadComposition'!$K$2:$K$99,"Ash",'4_BreadComposition'!$M$2:$M$99,"Protein",'4_BreadComposition'!$O$2:$O$99,"Fibre",'4_BreadComposition'!$P$2:$P$99),_xlpm.f,_xlfn._xlws.FILTER(_xlpm.col,(TRIM('4_BreadComposition'!$D$2:$D$99)=TRIM($H12))*('4_BreadComposition'!$E$2:$E$99=$F12)*('4_BreadComposition'!$B$2:$B$99=$G12)*ISNUMBER(_xlpm.col)),_xlfn.STDEV.S(_xlpm.f)),"")} | L12: 20% BSG_fraction+70ppmE | M12: 2 | N12: =AVERAGEIFS('5_Sensorial'!$N:$N, '5_Sensorial'!$B:$B, L12, '5_Sensorial'!$C:$C, M12) -> 62.5 | O12: {=_xlfn.STDEV.S(IF(('5_Sensorial'!$B:$B=$L12)*('5_Sensorial'!$C:$C=$M12),'5_Sensorial'!$N:$N)) / AVERAGEIFS('5_Sensorial'!$N:$N,'5_Sensorial'!$B:$B,$L12,'5_Sensorial'!$C:$C,$M12) * 100} -> 14.917679
A13: Protein | B13: 10% BSG Mixture | C13: {=AVERAGEIFS( _xlfn.SWITCH(A13,"Moisture",'1_RawMaterial'!K:K,"Ash",'1_RawMaterial'!L:L,"Protein",'1_RawMaterial'!N:N,"Gluten",'1_RawMaterial'!P:P,"Fibre",'1_RawMaterial'!Q:Q), '1_RawMaterial'!D:D, A13, '1_RawMaterial'!C:C, B13 )} -> 14.65 | D13: {=_xlfn.STDEV.S( _xlfn._xlws.FILTER( _xlfn.SWITCH(A13,"Moisture",'1_RawMaterial'!K:K,"Ash",'1_RawMaterial'!L:L,"Protein",'1_RawMaterial'!N:N,"Gluten",'1_RawMaterial'!P:P,"Fibre",'1_RawMaterial'!Q:Q), ('1_RawMaterial'!D:D=A13)*('1_RawMaterial'!C:C=B13) ) )} -> 0.49497475 | F13: Moisture | G13: B | H13: 10% BSG+140ppmE | I13: {=IFERROR(_xlfn.LET(_xlpm.col,_xlfn.SWITCH($F13,"Moisture",'4_BreadComposition'!$K$2:$K$99,"Ash",'4_BreadComposition'!$M$2:$M$99,"Protein",'4_BreadComposition'!$O$2:$O$99,"Fibre",'4_BreadComposition'!$P$2:$P$99),_xlpm.f,_xlfn._xlws.FILTER(_xlpm.col,(TRIM('4_BreadComposition'!$D$2:$D$99)=TRIM($H13))*('4_BreadComposition'!$E$2:$E$99=$F13)*('4_BreadComposition'!$B$2:$B$99=$G13)*ISNUMBER(_xlpm.col)),AVERAGE(_xlpm.f)),"")} -> 0.0857 | J13: {=IFERROR(_xlfn.LET(_xlpm.col,_xlfn.SWITCH($F13,"Moisture",'4_BreadComposition'!$K$2:$K$99,"Ash",'4_BreadComposition'!$M$2:$M$99,"Protein",'4_BreadComposition'!$O$2:$O$99,"Fibre",'4_BreadComposition'!$P$2:$P$99),_xlpm.f,_xlfn._xlws.FILTER(_xlpm.col,(TRIM('4_BreadComposition'!$D$2:$D$99)=TRIM($H13))*('4_BreadComposition'!$E$2:$E$99=$F13)*('4_BreadComposition'!$B$2:$B$99=$G13)*ISNUMBER(_xlpm.col)),_xlfn.STDEV.S(_xlpm.f)),"")} | L13: 10% BSG+140ppmE | M13: 2 | N13: =AVERAGEIFS('5_Sensorial'!$N:$N, '5_Sensorial'!$B:$B, L13, '5_Sensorial'!$C:$C, M13) -> 78.5625 | O13: {=_xlfn.STDEV.S(IF(('5_Sensorial'!$B:$B=$L13)*('5_Sensorial'!$C:$C=$M13),'5_Sensorial'!$N:$N)) / AVERAGEIFS('5_Sensorial'!$N:$N,'5_Sensorial'!$B:$B,$L13,'5_Sensorial'!$C:$C,$M13) * 100} -> 13.778455
A14: Protein | B14: 20% BSG Mixture | C14: {=AVERAGEIFS( _xlfn.SWITCH(A14,"Moisture",'1_RawMaterial'!K:K,"Ash",'1_RawMaterial'!L:L,"Protein",'1_RawMaterial'!N:N,"Gluten",'1_RawMaterial'!P:P,"Fibre",'1_RawMaterial'!Q:Q), '1_RawMaterial'!D:D, A14, '1_RawMaterial'!C:C, B14 )} -> 14.9 | D14: {=_xlfn.STDEV.S( _xlfn._xlws.FILTER( _xlfn.SWITCH(A14,"Moisture",'1_RawMaterial'!K:K,"Ash",'1_RawMaterial'!L:L,"Protein",'1_RawMaterial'!N:N,"Gluten",'1_RawMaterial'!P:P,"Fibre",'1_RawMaterial'!Q:Q), ('1_RawMaterial'!D:D=A14)*('1_RawMaterial'!C:C=B14) ) )} -> 0.14142136 | F14: Moisture | G14: B | H14: 20% BSG+140ppmE | I14: {=IFERROR(_xlfn.LET(_xlpm.col,_xlfn.SWITCH($F14,"Moisture",'4_BreadComposition'!$K$2:$K$99,"Ash",'4_BreadComposition'!$M$2:$M$99,"Protein",'4_BreadComposition'!$O$2:$O$99,"Fibre",'4_BreadComposition'!$P$2:$P$99),_xlpm.f,_xlfn._xlws.FILTER(_xlpm.col,(TRIM('4_BreadComposition'!$D$2:$D$99)=TRIM($H14))*('4_BreadComposition'!$E$2:$E$99=$F14)*('4_BreadComposition'!$B$2:$B$99=$G14)*ISNUMBER(_xlpm.col)),AVERAGE(_xlpm.f)),"")} -> 0.0852 | J14: {=IFERROR(_xlfn.LET(_xlpm.col,_xlfn.SWITCH($F14,"Moisture",'4_BreadComposition'!$K$2:$K$99,"Ash",'4_BreadComposition'!$M$2:$M$99,"Protein",'4_BreadComposition'!$O$2:$O$99,"Fibre",'4_BreadComposition'!$P$2:$P$99),_xlpm.f,_xlfn._xlws.FILTER(_xlpm.col,(TRIM('4_BreadComposition'!$D$2:$D$99)=TRIM($H14))*('4_BreadComposition'!$E$2:$E$99=$F14)*('4_BreadComposition'!$B$2:$B$99=$G14)*ISNUMBER(_xlpm.col)),_xlfn.STDEV.S(_xlpm.f)),"")} | L14: 20% BSG+140ppmE | M14: 2 | N14: =AVERAGEIFS('5_Sensorial'!$N:$N, '5_Sensorial'!$B:$B, L14, '5_Sensorial'!$C:$C, M14) -> 69.25 | O14: {=_xlfn.STDEV.S(IF(('5_Sensorial'!$B:$B=$L14)*('5_Sensorial'!$C:$C=$M14),'5_Sensorial'!$N:$N)) / AVERAGEIFS('5_Sensorial'!$N:$N,'5_Sensorial'!$B:$B,$L14,'5_Sensorial'!$C:$C,$M14) * 100} -> 20.090967
A15: Gluten | B15: Flour | C15: {=AVERAGEIFS( _xlfn.SWITCH(A15,"Moisture",'1_RawMaterial'!K:K,"Ash",'1_RawMaterial'!L:L,"Protein",'1_RawMaterial'!N:N,"Gluten",'1_RawMaterial'!P:P,"Fibre",'1_RawMaterial'!Q:Q), '1_RawMaterial'!D:D, A15, '1_RawMaterial'!C:C, B15 )} -> 0.29036092 | D15: {=_xlfn.STDEV.S( _xlfn._xlws.FILTER( _xlfn.SWITCH(A15,"Moisture",'1_RawMaterial'!K:K,"Ash",'1_RawMaterial'!L:L,"Protein",'1_RawMaterial'!N:N,"Gluten",'1_RawMaterial'!P:P,"Fibre",'1_RawMaterial'!Q:Q), ('1_RawMaterial'!D:D=A15)*('1_RawMaterial'!C:C=B15) ) )} -> 0 | F15: Moisture | G15: B | H15: 10% BSG_fraction+140ppmE | I15: {=IFERROR(_xlfn.LET(_xlpm.col,_xlfn.SWITCH($F15,"Moisture",'4_BreadComposition'!$K$2:$K$99,"Ash",'4_BreadComposition'!$M$2:$M$99,"Protein",'4_BreadComposition'!$O$2:$O$99,"Fibre",'4_BreadComposition'!$P$2:$P$99),_xlpm.f,_xlfn._xlws.FILTER(_xlpm.col,(TRIM('4_BreadComposition'!$D$2:$D$99)=TRIM($H15))*('4_BreadComposition'!$E$2:$E$99=$F15)*('4_BreadComposition'!$B$2:$B$99=$G15)*ISNUMBER(_xlpm.col)),AVERAGE(_xlpm.f)),"")} -> 0.0866 | J15: {=IFERROR(_xlfn.LET(_xlpm.col,_xlfn.SWITCH($F15,"Moisture",'4_BreadComposition'!$K$2:$K$99,"Ash",'4_BreadComposition'!$M$2:$M$99,"Protein",'4_BreadComposition'!$O$2:$O$99,"Fibre",'4_BreadComposition'!$P$2:$P$99),_xlpm.f,_xlfn._xlws.FILTER(_xlpm.col,(TRIM('4_BreadComposition'!$D$2:$D$99)=TRIM($H15))*('4_BreadComposition'!$E$2:$E$99=$F15)*('4_BreadComposition'!$B$2:$B$99=$G15)*ISNUMBER(_xlpm.col)),_xlfn.STDEV.S(_xlpm.f)),"")} | L15: 10% BSG_fraction+140ppmE | M15: 2 | N15: =AVERAGEIFS('5_Sensorial'!$N:$N, '5_Sensorial'!$B:$B, L15, '5_Sensorial'!$C:$C, M15) -> 72.4375 | O15: {=_xlfn.STDEV.S(IF(('5_Sensorial'!$B:$B=$L15)*('5_Sensorial'!$C:$C=$M15),'5_Sensorial'!$N:$N)) / AVERAGEIFS('5_Sensorial'!$N:$N,'5_Sensorial'!$B:$B,$L15,'5_Sensorial'!$C:$C,$M15) * 100} -> 12.228134
A16: Gluten | B16: 10% BSG Mixture | C16: {=AVERAGEIFS( _xlfn.SWITCH(A16,"Moisture",'1_RawMaterial'!K:K,"Ash",'1_RawMaterial'!L:L,"Protein",'1_RawMaterial'!N:N,"Gluten",'1_RawMaterial'!P:P,"Fibre",'1_RawMaterial'!Q:Q), '1_RawMaterial'!D:D, A16, '1_RawMaterial'!C:C, B16 )} -> 0.24027901 | D16: {=_xlfn.STDEV.S( _xlfn._xlws.FILTER( _xlfn.SWITCH(A16,"Moisture",'1_RawMaterial'!K:K,"Ash",'1_RawMaterial'!L:L,"Protein",'1_RawMaterial'!N:N,"Gluten",'1_RawMaterial'!P:P,"Fibre",'1_RawMaterial'!Q:Q), ('1_RawMaterial'!D:D=A16)*('1_RawMaterial'!C:C=B16) ) )} -> 0 | F16: Moisture | G16: B | H16: 20% BSG_fraction+140ppmE | I16: {=IFERROR(_xlfn.LET(_xlpm.col,_xlfn.SWITCH($F16,"Moisture",'4_BreadComposition'!$K$2:$K$99,"Ash",'4_BreadComposition'!$M$2:$M$99,"Protein",'4_BreadComposition'!$O$2:$O$99,"Fibre",'4_BreadComposition'!$P$2:$P$99),_xlpm.f,_xlfn._xlws.FILTER(_xlpm.col,(TRIM('4_BreadComposition'!$D$2:$D$99)=TRIM($H16))*('4_BreadComposition'!$E$2:$E$99=$F16)*('4_BreadComposition'!$B$2:$B$99=$G16)*ISNUMBER(_xlpm.col)),AVERAGE(_xlpm.f)),"")} -> 0.0835 | J16: {=IFERROR(_xlfn.LET(_xlpm.col,_xlfn.SWITCH($F16,"Moisture",'4_BreadComposition'!$K$2:$K$99,"Ash",'4_BreadComposition'!$M$2:$M$99,"Protein",'4_BreadComposition'!$O$2:$O$99,"Fibre",'4_BreadComposition'!$P$2:$P$99),_xlpm.f,_xlfn._xlws.FILTER(_xlpm.col,(TRIM('4_BreadComposition'!$D$2:$D$99)=TRIM($H16))*('4_BreadComposition'!$E$2:$E$99=$F16)*('4_BreadComposition'!$B$2:$B$99=$G16)*ISNUMBER(_xlpm.col)),_xlfn.STDEV.S(_xlpm.f)),"")} | L16: 20% BSG_fraction+140ppmE | M16: 2 | N16: =AVERAGEIFS('5_Sensorial'!$N:$N, '5_Sensorial'!$B:$B, L16, '5_Sensorial'!$C:$C, M16) -> 66.6875 | O16: {=_xlfn.STDEV.S(IF(('5_Sensorial'!$B:$B=$L16)*('5_Sensorial'!$C:$C=$M16),'5_Sensorial'!$N:$N)) / AVERAGEIFS('5_Sensorial'!$N:$N,'5_Sensorial'!$B:$B,$L16,'5_Sensorial'!$C:$C,$M16) * 100} -> 19.427625
A17: Gluten | B17: 20% BSG Mixture | C17: {=AVERAGEIFS( _xlfn.SWITCH(A17,"Moisture",'1_RawMaterial'!K:K,"Ash",'1_RawMaterial'!L:L,"Protein",'1_RawMaterial'!N:N,"Gluten",'1_RawMaterial'!P:P,"Fibre",'1_RawMaterial'!Q:Q), '1_RawMaterial'!D:D, A17, '1_RawMaterial'!C:C, B17 )} -> 0.22524056 | D17: {=_xlfn.STDEV.S( _xlfn._xlws.FILTER( _xlfn.SWITCH(A17,"Moisture",'1_RawMaterial'!K:K,"Ash",'1_RawMaterial'!L:L,"Protein",'1_RawMaterial'!N:N,"Gluten",'1_RawMaterial'!P:P,"Fibre",'1_RawMaterial'!Q:Q), ('1_RawMaterial'!D:D=A17)*('1_RawMaterial'!C:C=B17) ) )} -> 0.0070786277 | F17: Ash | G17: A | H17: Flour | I17: {=IFERROR(_xlfn.LET(_xlpm.col,_xlfn.SWITCH($F17,"Moisture",'4_BreadComposition'!$K$2:$K$99,"Ash",'4_BreadComposition'!$M$2:$M$99,"Protein",'4_BreadComposition'!$O$2:$O$99,"Fibre",'4_BreadComposition'!$P$2:$P$99),_xlpm.f,_xlfn._xlws.FILTER(_xlpm.col,(TRIM('4_BreadComposition'!$D$2:$D$99)=TRIM($H17))*('4_BreadComposition'!$E$2:$E$99=$F17)*('4_BreadComposition'!$B$2:$B$99=$G17)*ISNUMBER(_xlpm.col)),AVERAGE(_xlpm.f)),"")} -> 0.0058225257 | J17: {=IFERROR(_xlfn.LET(_xlpm.col,_xlfn.SWITCH($F17,"Moisture",'4_BreadComposition'!$K$2:$K$99,"Ash",'4_BreadComposition'!$M$2:$M$99,"Protein",'4_BreadComposition'!$O$2:$O$99,"Fibre",'4_BreadComposition'!$P$2:$P$99),_xlpm.f,_xlfn._xlws.FILTER(_xlpm.col,(TRIM('4_BreadComposition'!$D$2:$D$99)=TRIM($H17))*('4_BreadComposition'!$E$2:$E$99=$F17)*('4_BreadComposition'!$B$2:$B$99=$G17)*ISNUMBER(_xlpm.col)),_xlfn.STDEV.S(_xlpm.f)),"")} -> 0.00061100932
A18: Fibre | B18: Flour | C18: {=AVERAGEIFS( _xlfn.SWITCH(A18,"Moisture",'1_RawMaterial'!K:K,"Ash",'1_RawMaterial'!L:L,"Protein",'1_RawMaterial'!N:N,"Gluten",'1_RawMaterial'!P:P,"Fibre",'1_RawMaterial'!Q:Q), '1_RawMaterial'!D:D, A18, '1_RawMaterial'!C:C, B18 )} -> 0 | D18: {=_xlfn.STDEV.S( _xlfn._xlws.FILTER( _xlfn.SWITCH(A18,"Moisture",'1_RawMaterial'!K:K,"Ash",'1_RawMaterial'!L:L,"Protein",'1_RawMaterial'!N:N,"Gluten",'1_RawMaterial'!P:P,"Fibre",'1_RawMaterial'!Q:Q), ('1_RawMaterial'!D:D=A18)*('1_RawMaterial'!C:C=B18) ) )} -> 0 | F18: Ash | G18: A | H18: 10% BSG | I18: {=IFERROR(_xlfn.LET(_xlpm.col,_xlfn.SWITCH($F18,"Moisture",'4_BreadComposition'!$K$2:$K$99,"Ash",'4_BreadComposition'!$M$2:$M$99,"Protein",'4_BreadComposition'!$O$2:$O$99,"Fibre",'4_BreadComposition'!$P$2:$P$99),_xlpm.f,_xlfn._xlws.FILTER(_xlpm.col,(TRIM('4_BreadComposition'!$D$2:$D$99)=TRIM($H18))*('4_BreadComposition'!$E$2:$E$99=$F18)*('4_BreadComposition'!$B$2:$B$99=$G18)*ISNUMBER(_xlpm.col)),AVERAGE(_xlpm.f)),"")} -> 0.0088259764 | J18: {=IFERROR(_xlfn.LET(_xlpm.col,_xlfn.SWITCH($F18,"Moisture",'4_BreadComposition'!$K$2:$K$99,"Ash",'4_BreadComposition'!$M$2:$M$99,"Protein",'4_BreadComposition'!$O$2:$O$99,"Fibre",'4_BreadComposition'!$P$2:$P$99),_xlpm.f,_xlfn._xlws.FILTER(_xlpm.col,(TRIM('4_BreadComposition'!$D$2:$D$99)=TRIM($H18))*('4_BreadComposition'!$E$2:$E$99=$F18)*('4_BreadComposition'!$B$2:$B$99=$G18)*ISNUMBER(_xlpm.col)),_xlfn.STDEV.S(_xlpm.f)),"")} -> 0.00030288571
A19: Fibre | B19: BSG | C19: {=AVERAGEIFS( _xlfn.SWITCH(A19,"Moisture",'1_RawMaterial'!K:K,"Ash",'1_RawMaterial'!L:L,"Protein",'1_RawMaterial'!N:N,"Gluten",'1_RawMaterial'!P:P,"Fibre",'1_RawMaterial'!Q:Q), '1_RawMaterial'!D:D, A19, '1_RawMaterial'!C:C, B19 )} -> 0.1802 | D19: {=_xlfn.STDEV.S( _xlfn._xlws.FILTER( _xlfn.SWITCH(A19,"Moisture",'1_RawMaterial'!K:K,"Ash",'1_RawMaterial'!L:L,"Protein",'1_RawMaterial'!N:N,"Gluten",'1_RawMaterial'!P:P,"Fibre",'1_RawMaterial'!Q:Q), ('1_RawMaterial'!D:D=A19)*('1_RawMaterial'!C:C=B19) ) )} -> 0.0033941125 | F19: Ash | G19: A | H19: 20% BSG | I19: {=IFERROR(_xlfn.LET(_xlpm.col,_xlfn.SWITCH($F19,"Moisture",'4_BreadComposition'!$K$2:$K$99,"Ash",'4_BreadComposition'!$M$2:$M$99,"Protein",'4_BreadComposition'!$O$2:$O$99,"Fibre",'4_BreadComposition'!$P$2:$P$99),_xlpm.f,_xlfn._xlws.FILTER(_xlpm.col,(TRIM('4_BreadComposition'!$D$2:$D$99)=TRIM($H19))*('4_BreadComposition'!$E$2:$E$99=$F19)*('4_BreadComposition'!$B$2:$B$99=$G19)*ISNUMBER(_xlpm.col)),AVERAGE(_xlpm.f)),"")} -> 0.010562904 | J19: {=IFERROR(_xlfn.LET(_xlpm.col,_xlfn.SWITCH($F19,"Moisture",'4_BreadComposition'!$K$2:$K$99,"Ash",'4_BreadComposition'!$M$2:$M$99,"Protein",'4_BreadComposition'!$O$2:$O$99,"Fibre",'4_BreadComposition'!$P$2:$P$99),_xlpm.f,_xlfn._xlws.FILTER(_xlpm.col,(TRIM('4_BreadComposition'!$D$2:$D$99)=TRIM($H19))*('4_BreadComposition'!$E$2:$E$99=$F19)*('4_BreadComposition'!$B$2:$B$99=$G19)*ISNUMBER(_xlpm.col)),_xlfn.STDEV.S(_xlpm.f)),"")} -> 0.00052667426
A20: Fibre | B20: 10% BSG Mixture | C20: {=AVERAGEIFS( _xlfn.SWITCH(A20,"Moisture",'1_RawMaterial'!K:K,"Ash",'1_RawMaterial'!L:L,"Protein",'1_RawMaterial'!N:N,"Gluten",'1_RawMaterial'!P:P,"Fibre",'1_RawMaterial'!Q:Q), '1_RawMaterial'!D:D, A20, '1_RawMaterial'!C:C, B20 )} -> 0.01315 | D20: {=_xlfn.STDEV.S( _xlfn._xlws.FILTER( _xlfn.SWITCH(A20,"Moisture",'1_RawMaterial'!K:K,"Ash",'1_RawMaterial'!L:L,"Protein",'1_RawMaterial'!N:N,"Gluten",'1_RawMaterial'!P:P,"Fibre",'1_RawMaterial'!Q:Q), ('1_RawMaterial'!D:D=A20)*('1_RawMaterial'!C:C=B20) ) )} -> 0.0010606602 | F20: Ash | G20: A | H20: 10% BSG+70ppmE | I20: {=IFERROR(_xlfn.LET(_xlpm.col,_xlfn.SWITCH($F20,"Moisture",'4_BreadComposition'!$K$2:$K$99,"Ash",'4_BreadComposition'!$M$2:$M$99,"Protein",'4_BreadComposition'!$O$2:$O$99,"Fibre",'4_BreadComposition'!$P$2:$P$99),_xlpm.f,_xlfn._xlws.FILTER(_xlpm.col,(TRIM('4_BreadComposition'!$D$2:$D$99)=TRIM($H20))*('4_BreadComposition'!$E$2:$E$99=$F20)*('4_BreadComposition'!$B$2:$B$99=$G20)*ISNUMBER(_xlpm.col)),AVERAGE(_xlpm.f)),"")} -> 0.0098364826 | J20: {=IFERROR(_xlfn.LET(_xlpm.col,_xlfn.SWITCH($F20,"Moisture",'4_BreadComposition'!$K$2:$K$99,"Ash",'4_BreadComposition'!$M$2:$M$99,"Protein",'4_BreadComposition'!$O$2:$O$99,"Fibre",'4_BreadComposition'!$P$2:$P$99),_xlpm.f,_xlfn._xlws.FILTER(_xlpm.col,(TRIM('4_BreadComposition'!$D$2:$D$99)=TRIM($H20))*('4_BreadComposition'!$E$2:$E$99=$F20)*('4_BreadComposition'!$B$2:$B$99=$G20)*ISNUMBER(_xlpm.col)),_xlfn.STDEV.S(_xlpm.f)),"")} -> 0.0007473504
A21: Fibre | B21: 20% BSG Mixture | C21: {=AVERAGEIFS( _xlfn.SWITCH(A21,"Moisture",'1_RawMaterial'!K:K,"Ash",'1_RawMaterial'!L:L,"Protein",'1_RawMaterial'!N:N,"Gluten",'1_RawMaterial'!P:P,"Fibre",'1_RawMaterial'!Q:Q), '1_RawMaterial'!D:D, A21, '1_RawMaterial'!C:C, B21 )} -> 0.0314 | D21: {=_xlfn.STDEV.S( _xlfn._xlws.FILTER( _xlfn.SWITCH(A21,"Moisture",'1_RawMaterial'!K:K,"Ash",'1_RawMaterial'!L:L,"Protein",'1_RawMaterial'!N:N,"Gluten",'1_RawMaterial'!P:P,"Fibre",'1_RawMaterial'!Q:Q), ('1_RawMaterial'!D:D=A21)*('1_RawMaterial'!C:C=B21) ) )} -> 0.00042426407 | F21: Ash | G21: A | H21: 20% BSG+70ppmE | I21: {=IFERROR(_xlfn.LET(_xlpm.col,_xlfn.SWITCH($F21,"Moisture",'4_BreadComposition'!$K$2:$K$99,"Ash",'4_BreadComposition'!$M$2:$M$99,"Protein",'4_BreadComposition'!$O$2:$O$99,"Fibre",'4_BreadComposition'!$P$2:$P$99),_xlpm.f,_xlfn._xlws.FILTER(_xlpm.col,(TRIM('4_BreadComposition'!$D$2:$D$99)=TRIM($H21))*('4_BreadComposition'!$E$2:$E$99=$F21)*('4_BreadComposition'!$B$2:$B$99=$G21)*ISNUMBER(_xlpm.col)),AVERAGE(_xlpm.f)),"")} -> 0.014668877 | J21: {=IFERROR(_xlfn.LET(_xlpm.col,_xlfn.SWITCH($F21,"Moisture",'4_BreadComposition'!$K$2:$K$99,"Ash",'4_BreadComposition'!$M$2:$M$99,"Protein",'4_BreadComposition'!$O$2:$O$99,"Fibre",'4_BreadComposition'!$P$2:$P$99),_xlpm.f,_xlfn._xlws.FILTER(_xlpm.col,(TRIM('4_BreadComposition'!$D$2:$D$99)=TRIM($H21))*('4_BreadComposition'!$E$2:$E$99=$F21)*('4_BreadComposition'!$B$2:$B$99=$G21)*ISNUMBER(_xlpm.col)),_xlfn.STDEV.S(_xlpm.f)),"")} -> 0.0012554128
F22: Ash | G22: B | H22: Flour | I22: {=IFERROR(_xlfn.LET(_xlpm.col,_xlfn.SWITCH($F22,"Moisture",'4_BreadComposition'!$K$2:$K$99,"Ash",'4_BreadComposition'!$M$2:$M$99,"Protein",'4_BreadComposition'!$O$2:$O$99,"Fibre",'4_BreadComposition'!$P$2:$P$99),_xlpm.f,_xlfn._xlws.FILTER(_xlpm.col,(TRIM('4_BreadComposition'!$D$2:$D$99)=TRIM($H22))*('4_BreadComposition'!$E$2:$E$99=$F22)*('4_BreadComposition'!$B$2:$B$99=$G22)*ISNUMBER(_xlpm.col)),AVERAGE(_xlpm.f)),"")} -> 0.0087 | J22: {=IFERROR(_xlfn.LET(_xlpm.col,_xlfn.SWITCH($F22,"Moisture",'4_BreadComposition'!$K$2:$K$99,"Ash",'4_BreadComposition'!$M$2:$M$99,"Protein",'4_BreadComposition'!$O$2:$O$99,"Fibre",'4_BreadComposition'!$P$2:$P$99),_xlpm.f,_xlfn._xlws.FILTER(_xlpm.col,(TRIM('4_BreadComposition'!$D$2:$D$99)=TRIM($H22))*('4_BreadComposition'!$E$2:$E$99=$F22)*('4_BreadComposition'!$B$2:$B$99=$G22)*ISNUMBER(_xlpm.col)),_xlfn.STDEV.S(_xlpm.f)),"")} -> 0.00056568542
F23: Ash | G23: B | H23: 10% BSG+70ppmE | I23: {=IFERROR(_xlfn.LET(_xlpm.col,_xlfn.SWITCH($F23,"Moisture",'4_BreadComposition'!$K$2:$K$99,"Ash",'4_BreadComposition'!$M$2:$M$99,"Protein",'4_BreadComposition'!$O$2:$O$99,"Fibre",'4_BreadComposition'!$P$2:$P$99),_xlpm.f,_xlfn._xlws.FILTER(_xlpm.col,(TRIM('4_BreadComposition'!$D$2:$D$99)=TRIM($H23))*('4_BreadComposition'!$E$2:$E$99=$F23)*('4_BreadComposition'!$B$2:$B$99=$G23)*ISNUMBER(_xlpm.col)),AVERAGE(_xlpm.f)),"")} -> 0.01265 | J23: {=IFERROR(_xlfn.LET(_xlpm.col,_xlfn.SWITCH($F23,"Moisture",'4_BreadComposition'!$K$2:$K$99,"Ash",'4_BreadComposition'!$M$2:$M$99,"Protein",'4_BreadComposition'!$O$2:$O$99,"Fibre",'4_BreadComposition'!$P$2:$P$99),_xlpm.f,_xlfn._xlws.FILTER(_xlpm.col,(TRIM('4_BreadComposition'!$D$2:$D$99)=TRIM($H23))*('4_BreadComposition'!$E$2:$E$99=$F23)*('4_BreadComposition'!$B$2:$B$99=$G23)*ISNUMBER(_xlpm.col)),_xlfn.STDEV.S(_xlpm.f)),"")} -> 0.0013435029
F24: Ash | G24: B | H24: 20% BSG+70ppmE | I24: {=IFERROR(_xlfn.LET(_xlpm.col,_xlfn.SWITCH($F24,"Moisture",'4_BreadComposition'!$K$2:$K$99,"Ash",'4_BreadComposition'!$M$2:$M$99,"Protein",'4_BreadComposition'!$O$2:$O$99,"Fibre",'4_BreadComposition'!$P$2:$P$99),_xlpm.f,_xlfn._xlws.FILTER(_xlpm.col,(TRIM('4_BreadComposition'!$D$2:$D$99)=TRIM($H24))*('4_BreadComposition'!$E$2:$E$99=$F24)*('4_BreadComposition'!$B$2:$B$99=$G24)*ISNUMBER(_xlpm.col)),AVERAGE(_xlpm.f)),"")} -> 0.01575 | J24: {=IFERROR(_xlfn.LET(_xlpm.col,_xlfn.SWITCH($F24,"Moisture",'4_BreadComposition'!$K$2:$K$99,"Ash",'4_BreadComposition'!$M$2:$M$99,"Protein",'4_BreadComposition'!$O$2:$O$99,"Fibre",'4_BreadComposition'!$P$2:$P$99),_xlpm.f,_xlfn._xlws.FILTER(_xlpm.col,(TRIM('4_BreadComposition'!$D$2:$D$99)=TRIM($H24))*('4_BreadComposition'!$E$2:$E$99=$F24)*('4_BreadComposition'!$B$2:$B$99=$G24)*ISNUMBER(_xlpm.col)),_xlfn.STDEV.S(_xlpm.f)),"")} -> 0.00035355339
F25: Ash | G25: B | H25: 10% BSG_fraction+70ppmE | I25: {=IFERROR(_xlfn.LET(_xlpm.col,_xlfn.SWITCH($F25,"Moisture",'4_BreadComposition'!$K$2:$K$99,"Ash",'4_BreadComposition'!$M$2:$M$99,"Protein",'4_BreadComposition'!$O$2:$O$99,"Fibre",'4_BreadComposition'!$P$2:$P$99),_xlpm.f,_xlfn._xlws.FILTER(_xlpm.col,(TRIM('4_BreadComposition'!$D$2:$D$99)=TRIM($H25))*('4_BreadComposition'!$E$2:$E$99=$F25)*('4_BreadComposition'!$B$2:$B$99=$G25)*ISNUMBER(_xlpm.col)),AVERAGE(_xlpm.f)),"")} -> 0.01125 | J25: {=IFERROR(_xlfn.LET(_xlpm.col,_xlfn.SWITCH($F25,"Moisture",'4_BreadComposition'!$K$2:$K$99,"Ash",'4_BreadComposition'!$M$2:$M$99,"Protein",'4_BreadComposition'!$O$2:$O$99,"Fibre",'4_BreadComposition'!$P$2:$P$99),_xlpm.f,_xlfn._xlws.FILTER(_xlpm.col,(TRIM('4_BreadComposition'!$D$2:$D$99)=TRIM($H25))*('4_BreadComposition'!$E$2:$E$99=$F25)*('4_BreadComposition'!$B$2:$B$99=$G25)*ISNUMBER(_xlpm.col)),_xlfn.STDEV.S(_xlpm.f)),"")} -> 0.0016263456
F26: Ash | G26: B | H26: 20% BSG_fraction+70ppmE | I26: {=IFERROR(_xlfn.LET(_xlpm.col,_xlfn.SWITCH($F26,"Moisture",'4_BreadComposition'!$K$2:$K$99,"Ash",'4_BreadComposition'!$M$2:$M$99,"Protein",'4_BreadComposition'!$O$2:$O$99,"Fibre",'4_BreadComposition'!$P$2:$P$99),_xlpm.f,_xlfn._xlws.FILTER(_xlpm.col,(TRIM('4_BreadComposition'!$D$2:$D$99)=TRIM($H26))*('4_BreadComposition'!$E$2:$E$99=$F26)*('4_BreadComposition'!$B$2:$B$99=$G26)*ISNUMBER(_xlpm.col)),AVERAGE(_xlpm.f)),"")} -> 0.01515 | J26: {=IFERROR(_xlfn.LET(_xlpm.col,_xlfn.SWITCH($F26,"Moisture",'4_BreadComposition'!$K$2:$K$99,"Ash",'4_BreadComposition'!$M$2:$M$99,"Protein",'4_BreadComposition'!$O$2:$O$99,"Fibre",'4_BreadComposition'!$P$2:$P$99),_xlpm.f,_xlfn._xlws.FILTER(_xlpm.col,(TRIM('4_BreadComposition'!$D$2:$D$99)=TRIM($H26))*('4_BreadComposition'!$E$2:$E$99=$F26)*('4_BreadComposition'!$B$2:$B$99=$G26)*ISNUMBER(_xlpm.col)),_xlfn.STDEV.S(_xlpm.f)),"")} -> 0.0012020815
F27: Ash | G27: B | H27: 10% BSG+140ppmE | I27: {=IFERROR(_xlfn.LET(_xlpm.col,_xlfn.SWITCH($F27,"Moisture",'4_BreadComposition'!$K$2:$K$99,"Ash",'4_BreadComposition'!$M$2:$M$99,"Protein",'4_BreadComposition'!$O$2:$O$99,"Fibre",'4_BreadComposition'!$P$2:$P$99),_xlpm.f,_xlfn._xlws.FILTER(_xlpm.col,(TRIM('4_BreadComposition'!$D$2:$D$99)=TRIM($H27))*('4_BreadComposition'!$E$2:$E$99=$F27)*('4_BreadComposition'!$B$2:$B$99=$G27)*ISNUMBER(_xlpm.col)),AVERAGE(_xlpm.f)),"")} -> 0.01445 | J27: {=IFERROR(_xlfn.LET(_xlpm.col,_xlfn.SWITCH($F27,"Moisture",'4_BreadComposition'!$K$2:$K$99,"Ash",'4_BreadComposition'!$M$2:$M$99,"Protein",'4_BreadComposition'!$O$2:$O$99,"Fibre",'4_BreadComposition'!$P$2:$P$99),_xlpm.f,_xlfn._xlws.FILTER(_xlpm.col,(TRIM('4_BreadComposition'!$D$2:$D$99)=TRIM($H27))*('4_BreadComposition'!$E$2:$E$99=$F27)*('4_BreadComposition'!$B$2:$B$99=$G27)*ISNUMBER(_xlpm.col)),_xlfn.STDEV.S(_xlpm.f)),"")} -> 0.00035355339
F28: Ash | G28: B | H28: 20% BSG+140ppmE | I28: {=IFERROR(_xlfn.LET(_xlpm.col,_xlfn.SWITCH($F28,"Moisture",'4_BreadComposition'!$K$2:$K$99,"Ash",'4_BreadComposition'!$M$2:$M$99,"Protein",'4_BreadComposition'!$O$2:$O$99,"Fibre",'4_BreadComposition'!$P$2:$P$99),_xlpm.f,_xlfn._xlws.FILTER(_xlpm.col,(TRIM('4_BreadComposition'!$D$2:$D$99)=TRIM($H28))*('4_BreadComposition'!$E$2:$E$99=$F28)*('4_BreadComposition'!$B$2:$B$99=$G28)*ISNUMBER(_xlpm.col)),AVERAGE(_xlpm.f)),"")} -> 0.01865 | J28: {=IFERROR(_xlfn.LET(_xlpm.col,_xlfn.SWITCH($F28,"Moisture",'4_BreadComposition'!$K$2:$K$99,"Ash",'4_BreadComposition'!$M$2:$M$99,"Protein",'4_BreadComposition'!$O$2:$O$99,"Fibre",'4_BreadComposition'!$P$2:$P$99),_xlpm.f,_xlfn._xlws.FILTER(_xlpm.col,(TRIM('4_BreadComposition'!$D$2:$D$99)=TRIM($H28))*('4_BreadComposition'!$E$2:$E$99=$F28)*('4_BreadComposition'!$B$2:$B$99=$G28)*ISNUMBER(_xlpm.col)),_xlfn.STDEV.S(_xlpm.f)),"")} -> 0.0027577164
F29: Ash | G29: B | H29: 10% BSG_fraction+140ppmE | I29: {=IFERROR(_xlfn.LET(_xlpm.col,_xlfn.SWITCH($F29,"Moisture",'4_BreadComposition'!$K$2:$K$99,"Ash",'4_BreadComposition'!$M$2:$M$99,"Protein",'4_BreadComposition'!$O$2:$O$99,"Fibre",'4_BreadComposition'!$P$2:$P$99),_xlpm.f,_xlfn._xlws.FILTER(_xlpm.col,(TRIM('4_BreadComposition'!$D$2:$D$99)=TRIM($H29))*('4_BreadComposition'!$E$2:$E$99=$F29)*('4_BreadComposition'!$B$2:$B$99=$G29)*ISNUMBER(_xlpm.col)),AVERAGE(_xlpm.f)),"")} -> 0.01335 | J29: {=IFERROR(_xlfn.LET(_xlpm.col,_xlfn.SWITCH($F29,"Moisture",'4_BreadComposition'!$K$2:$K$99,"Ash",'4_BreadComposition'!$M$2:$M$99,"Protein",'4_BreadComposition'!$O$2:$O$99,"Fibre",'4_BreadComposition'!$P$2:$P$99),_xlpm.f,_xlfn._xlws.FILTER(_xlpm.col,(TRIM('4_BreadComposition'!$D$2:$D$99)=TRIM($H29))*('4_BreadComposition'!$E$2:$E$99=$F29)*('4_BreadComposition'!$B$2:$B$99=$G29)*ISNUMBER(_xlpm.col)),_xlfn.STDEV.S(_xlpm.f)),"")} -> 0.0030405592
F30: Ash | G30: B | H30: 20% BSG_fraction+140ppmE | I30: {=IFERROR(_xlfn.LET(_xlpm.col,_xlfn.SWITCH($F30,"Moisture",'4_BreadComposition'!$K$2:$K$99,"Ash",'4_BreadComposition'!$M$2:$M$99,"Protein",'4_BreadComposition'!$O$2:$O$99,"Fibre",'4_BreadComposition'!$P$2:$P$99),_xlpm.f,_xlfn._xlws.FILTER(_xlpm.col,(TRIM('4_BreadComposition'!$D$2:$D$99)=TRIM($H30))*('4_BreadComposition'!$E$2:$E$99=$F30)*('4_BreadComposition'!$B$2:$B$99=$G30)*ISNUMBER(_xlpm.col)),AVERAGE(_xlpm.f)),"")} -> 0.01525 | J30: {=IFERROR(_xlfn.LET(_xlpm.col,_xlfn.SWITCH($F30,"Moisture",'4_BreadComposition'!$K$2:$K$99,"Ash",'4_BreadComposition'!$M$2:$M$99,"Protein",'4_BreadComposition'!$O$2:$O$99,"Fibre",'4_BreadComposition'!$P$2:$P$99),_xlpm.f,_xlfn._xlws.FILTER(_xlpm.col,(TRIM('4_BreadComposition'!$D$2:$D$99)=TRIM($H30))*('4_BreadComposition'!$E$2:$E$99=$F30)*('4_BreadComposition'!$B$2:$B$99=$G30)*ISNUMBER(_xlpm.col)),_xlfn.STDEV.S(_xlpm.f)),"")} -> 0.0024748737
F31: Protein | G31: A | H31: Flour | I31: {=IFERROR(_xlfn.LET(_xlpm.col,_xlfn.SWITCH($F31,"Moisture",'4_BreadComposition'!$K$2:$K$99,"Ash",'4_BreadComposition'!$M$2:$M$99,"Protein",'4_BreadComposition'!$O$2:$O$99,"Fibre",'4_BreadComposition'!$P$2:$P$99),_xlpm.f,_xlfn._xlws.FILTER(_xlpm.col,(TRIM('4_BreadComposition'!$D$2:$D$99)=TRIM($H31))*('4_BreadComposition'!$E$2:$E$99=$F31)*('4_BreadComposition'!$B$2:$B$99=$G31)*ISNUMBER(_xlpm.col)),AVERAGE(_xlpm.f)),"")} -> 0.1208 | J31: {=IFERROR(_xlfn.LET(_xlpm.col,_xlfn.SWITCH($F31,"Moisture",'4_BreadComposition'!$K$2:$K$99,"Ash",'4_BreadComposition'!$M$2:$M$99,"Protein",'4_BreadComposition'!$O$2:$O$99,"Fibre",'4_BreadComposition'!$P$2:$P$99),_xlpm.f,_xlfn._xlws.FILTER(_xlpm.col,(TRIM('4_BreadComposition'!$D$2:$D$99)=TRIM($H31))*('4_BreadComposition'!$E$2:$E$99=$F31)*('4_BreadComposition'!$B$2:$B$99=$G31)*ISNUMBER(_xlpm.col)),_xlfn.STDEV.S(_xlpm.f)),"")} -> 0.00056568542
F32: Protein | G32: A | H32: 10% BSG | I32: {=IFERROR(_xlfn.LET(_xlpm.col,_xlfn.SWITCH($F32,"Moisture",'4_BreadComposition'!$K$2:$K$99,"Ash",'4_BreadComposition'!$M$2:$M$99,"Protein",'4_BreadComposition'!$O$2:$O$99,"Fibre",'4_BreadComposition'!$P$2:$P$99),_xlpm.f,_xlfn._xlws.FILTER(_xlpm.col,(TRIM('4_BreadComposition'!$D$2:$D$99)=TRIM($H32))*('4_BreadComposition'!$E$2:$E$99=$F32)*('4_BreadComposition'!$B$2:$B$99=$G32)*ISNUMBER(_xlpm.col)),AVERAGE(_xlpm.f)),"")} -> 0.13395 | J32: {=IFERROR(_xlfn.LET(_xlpm.col,_xlfn.SWITCH($F32,"Moisture",'4_BreadComposition'!$K$2:$K$99,"Ash",'4_BreadComposition'!$M$2:$M$99,"Protein",'4_BreadComposition'!$O$2:$O$99,"Fibre",'4_BreadComposition'!$P$2:$P$99),_xlpm.f,_xlfn._xlws.FILTER(_xlpm.col,(TRIM('4_BreadComposition'!$D$2:$D$99)=TRIM($H32))*('4_BreadComposition'!$E$2:$E$99=$F32)*('4_BreadComposition'!$B$2:$B$99=$G32)*ISNUMBER(_xlpm.col)),_xlfn.STDEV.S(_xlpm.f)),"")} -> 0.0054447222
F33: Protein | G33: A | H33: 20% BSG | I33: {=IFERROR(_xlfn.LET(_xlpm.col,_xlfn.SWITCH($F33,"Moisture",'4_BreadComposition'!$K$2:$K$99,"Ash",'4_BreadComposition'!$M$2:$M$99,"Protein",'4_BreadComposition'!$O$2:$O$99,"Fibre",'4_BreadComposition'!$P$2:$P$99),_xlpm.f,_xlfn._xlws.FILTER(_xlpm.col,(TRIM('4_BreadComposition'!$D$2:$D$99)=TRIM($H33))*('4_BreadComposition'!$E$2:$E$99=$F33)*('4_BreadComposition'!$B$2:$B$99=$G33)*ISNUMBER(_xlpm.col)),AVERAGE(_xlpm.f)),"")} -> 0.1373 | J33: {=IFERROR(_xlfn.LET(_xlpm.col,_xlfn.SWITCH($F33,"Moisture",'4_BreadComposition'!$K$2:$K$99,"Ash",'4_BreadComposition'!$M$2:$M$99,"Protein",'4_BreadComposition'!$O$2:$O$99,"Fibre",'4_BreadComposition'!$P$2:$P$99),_xlpm.f,_xlfn._xlws.FILTER(_xlpm.col,(TRIM('4_BreadComposition'!$D$2:$D$99)=TRIM($H33))*('4_BreadComposition'!$E$2:$E$99=$F33)*('4_BreadComposition'!$B$2:$B$99=$G33)*ISNUMBER(_xlpm.col)),_xlfn.STDEV.S(_xlpm.f)),"")} -> 0.0016970563
... F58: Fibre | G58: B | H58: 20% BSG_fraction+140ppmE | I58: {=IFERROR(_xlfn.LET(_xlpm.col,_xlfn.SWITCH($F58,"Moisture",'4_BreadComposition'!$K$2:$K$99,"Ash",'4_BreadComposition'!$M$2:$M$99,"Protein",'4_BreadComposition'!$O$2:$O$99,"Fibre",'4_BreadComposition'!$P$2:$P$99),_xlpm.f,_xlfn._xlws.FILTER(_xlpm.col,(TRIM('4_BreadComposition'!$D$2:$D$99)=TRIM($H58))*('4_BreadComposition'!$E$2:$E$99=$F58)*('4_BreadComposition'!$B$2:$B$99=$G58)*ISNUMBER(_xlpm.col)),AVERAGE(_xlpm.f)),"")} -> 0.0014 | J58: {=IFERROR(_xlfn.LET(_xlpm.col,_xlfn.SWITCH($F58,"Moisture",'4_BreadComposition'!$K$2:$K$99,"Ash",'4_BreadComposition'!$M$2:$M$99,"Protein",'4_BreadComposition'!$O$2:$O$99,"Fibre",'4_BreadComposition'!$P$2:$P$99),_xlpm.f,_xlfn._xlws.FILTER(_xlpm.col,(TRIM('4_BreadComposition'!$D$2:$D$99)=TRIM($H58))*('4_BreadComposition'!$E$2:$E$99=$F58)*('4_BreadComposition'!$B$2:$B$99=$G58)*ISNUMBER(_xlpm.col)),_xlfn.STDEV.S(_xlpm.f)),"")} -> 0.001979899
F59: Volume | G59: A | H59: Flour | I59: {=IFERROR(_xlfn.LET(_xlpm.col,_xlfn.SWITCH($F59,"Volume",'3_BreadFormulation&measurements'!$M$3:$M$20,"H/W ratio",'3_BreadFormulation&measurements'!$N$3:$N$20),_xlpm.f,_xlfn._xlws.FILTER(_xlpm.col,(SUBSTITUTE(TRIM('3_BreadFormulation&measurements'!$C$3:$C$20)," ","_")=SUBSTITUTE(TRIM($H59)," ","_"))*('3_BreadFormulation&measurements'!$A$3:$A$20=$G59)*ISNUMBER(_xlpm.col)),AVERAGE(_xlpm.f)),"")} -> 925 | J59: {=IFERROR(_xlfn.LET(_xlpm.col,_xlfn.SWITCH($F59,"Volume",'3_BreadFormulation&measurements'!$M$3:$M$20,"H/W ratio",'3_BreadFormulation&measurements'!$N$3:$N$20),_xlpm.f,_xlfn._xlws.FILTER(_xlpm.col,(SUBSTITUTE(TRIM('3_BreadFormulation&measurements'!$C$3:$C$20)," ","_")=SUBSTITUTE(TRIM($H59)," ","_"))*('3_BreadFormulation&measurements'!$A$3:$A$20=$G59)*ISNUMBER(_xlpm.col)),_xlfn.STDEV.S(_xlpm.f)),"")}
F60: Volume | G60: A | H60: 10% BSG | I60: {=IFERROR(_xlfn.LET(_xlpm.col,_xlfn.SWITCH($F60,"Volume",'3_BreadFormulation&measurements'!$M$3:$M$20,"H/W ratio",'3_BreadFormulation&measurements'!$N$3:$N$20),_xlpm.f,_xlfn._xlws.FILTER(_xlpm.col,(SUBSTITUTE(TRIM('3_BreadFormulation&measurements'!$C$3:$C$20)," ","_")=SUBSTITUTE(TRIM($H60)," ","_"))*('3_BreadFormulation&measurements'!$A$3:$A$20=$G60)*ISNUMBER(_xlpm.col)),AVERAGE(_xlpm.f)),"")} -> 775 | J60: {=IFERROR(_xlfn.LET(_xlpm.col,_xlfn.SWITCH($F60,"Volume",'3_BreadFormulation&measurements'!$M$3:$M$20,"H/W ratio",'3_BreadFormulation&measurements'!$N$3:$N$20),_xlpm.f,_xlfn._xlws.FILTER(_xlpm.col,(SUBSTITUTE(TRIM('3_BreadFormulation&measurements'!$C$3:$C$20)," ","_")=SUBSTITUTE(TRIM($H60)," ","_"))*('3_BreadFormulation&measurements'!$A$3:$A$20=$G60)*ISNUMBER(_xlpm.col)),_xlfn.STDEV.S(_xlpm.f)),"")}
F61: Volume | G61: A | H61: 20% BSG | I61: {=IFERROR(_xlfn.LET(_xlpm.col,_xlfn.SWITCH($F61,"Volume",'3_BreadFormulation&measurements'!$M$3:$M$20,"H/W ratio",'3_BreadFormulation&measurements'!$N$3:$N$20),_xlpm.f,_xlfn._xlws.FILTER(_xlpm.col,(SUBSTITUTE(TRIM('3_BreadFormulation&measurements'!$C$3:$C$20)," ","_")=SUBSTITUTE(TRIM($H61)," ","_"))*('3_BreadFormulation&measurements'!$A$3:$A$20=$G61)*ISNUMBER(_xlpm.col)),AVERAGE(_xlpm.f)),"")} -> 680 | J61: {=IFERROR(_xlfn.LET(_xlpm.col,_xlfn.SWITCH($F61,"Volume",'3_BreadFormulation&measurements'!$M$3:$M$20,"H/W ratio",'3_BreadFormulation&measurements'!$N$3:$N$20),_xlpm.f,_xlfn._xlws.FILTER(_xlpm.col,(SUBSTITUTE(TRIM('3_BreadFormulation&measurements'!$C$3:$C$20)," ","_")=SUBSTITUTE(TRIM($H61)," ","_"))*('3_BreadFormulation&measurements'!$A$3:$A$20=$G61)*ISNUMBER(_xlpm.col)),_xlfn.STDEV.S(_xlpm.f)),"")}
F62: Volume | G62: A | H62: 10% BSG+70ppmE | I62: {=IFERROR(_xlfn.LET(_xlpm.col,_xlfn.SWITCH($F62,"Volume",'3_BreadFormulation&measurements'!$M$3:$M$20,"H/W ratio",'3_BreadFormulation&measurements'!$N$3:$N$20),_xlpm.f,_xlfn._xlws.FILTER(_xlpm.col,(SUBSTITUTE(TRIM('3_BreadFormulation&measurements'!$C$3:$C$20)," ","_")=SUBSTITUTE(TRIM($H62)," ","_"))*('3_BreadFormulation&measurements'!$A$3:$A$20=$G62)*ISNUMBER(_xlpm.col)),AVERAGE(_xlpm.f)),"")} -> 825 | J62: {=IFERROR(_xlfn.LET(_xlpm.col,_xlfn.SWITCH($F62,"Volume",'3_BreadFormulation&measurements'!$M$3:$M$20,"H/W ratio",'3_BreadFormulation&measurements'!$N$3:$N$20),_xlpm.f,_xlfn._xlws.FILTER(_xlpm.col,(SUBSTITUTE(TRIM('3_BreadFormulation&measurements'!$C$3:$C$20)," ","_")=SUBSTITUTE(TRIM($H62)," ","_"))*('3_BreadFormulation&measurements'!$A$3:$A$20=$G62)*ISNUMBER(_xlpm.col)),_xlfn.STDEV.S(_xlpm.f)),"")}
F63: Volume | G63: A | H63: 20% BSG+70ppmE | I63: {=IFERROR(_xlfn.LET(_xlpm.col,_xlfn.SWITCH($F63,"Volume",'3_BreadFormulation&measurements'!$M$3:$M$20,"H/W ratio",'3_BreadFormulation&measurements'!$N$3:$N$20),_xlpm.f,_xlfn._xlws.FILTER(_xlpm.col,(SUBSTITUTE(TRIM('3_BreadFormulation&measurements'!$C$3:$C$20)," ","_")=SUBSTITUTE(TRIM($H63)," ","_"))*('3_BreadFormulation&measurements'!$A$3:$A$20=$G63)*ISNUMBER(_xlpm.col)),AVERAGE(_xlpm.f)),"")} -> 725 | J63: {=IFERROR(_xlfn.LET(_xlpm.col,_xlfn.SWITCH($F63,"Volume",'3_BreadFormulation&measurements'!$M$3:$M$20,"H/W ratio",'3_BreadFormulation&measurements'!$N$3:$N$20),_xlpm.f,_xlfn._xlws.FILTER(_xlpm.col,(SUBSTITUTE(TRIM('3_BreadFormulation&measurements'!$C$3:$C$20)," ","_")=SUBSTITUTE(TRIM($H63)," ","_"))*('3_BreadFormulation&measurements'!$A$3:$A$20=$G63)*ISNUMBER(_xlpm.col)),_xlfn.STDEV.S(_xlpm.f)),"")}
F64: Volume | G64: B | H64: Flour | I64: {=IFERROR(_xlfn.LET(_xlpm.col,_xlfn.SWITCH($F64,"Volume",'3_BreadFormulation&measurements'!$M$3:$M$20,"H/W ratio",'3_BreadFormulation&measurements'!$N$3:$N$20),_xlpm.f,_xlfn._xlws.FILTER(_xlpm.col,(SUBSTITUTE(TRIM('3_BreadFormulation&measurements'!$C$3:$C$20)," ","_")=SUBSTITUTE(TRIM($H64)," ","_"))*('3_BreadFormulation&measurements'!$A$3:$A$20=$G64)*ISNUMBER(_xlpm.col)),AVERAGE(_xlpm.f)),"")} -> 975 | J64: {=IFERROR(_xlfn.LET(_xlpm.col,_xlfn.SWITCH($F64,"Volume",'3_BreadFormulation&measurements'!$M$3:$M$20,"H/W ratio",'3_BreadFormulation&measurements'!$N$3:$N$20),_xlpm.f,_xlfn._xlws.FILTER(_xlpm.col,(SUBSTITUTE(TRIM('3_BreadFormulation&measurements'!$C$3:$C$20)," ","_")=SUBSTITUTE(TRIM($H64)," ","_"))*('3_BreadFormulation&measurements'!$A$3:$A$20=$G64)*ISNUMBER(_xlpm.col)),_xlfn.STDEV.S(_xlpm.f)),"")}
...

Sheet 1_RawMaterial
